Workbook

Sheet PLANO.CONTAS
A1: 1 | B1: Código | C1: T | D1: Classificação | E1: Nome | J1: Grau | K1: Grupo de Contas 1 | L1: Cod Grupo 1 | M1: Grupo de Contas 2
A2: 2 | B2: 17 | C2: S | D2: 1 | E2: ATIVO | J2: 1
A3: 3 | B3: 23 | C3: S | D3: 1.1 | F3: ATIVO CIRCULANTE | J3: 2
A4: 4 | B4: 30 | C4: S | D4: 1.1.01 | G4: DISPONIBILIDADES | J4: 3
A5: 5 | B5: 46 | C5: S | D5: 1.1.01.01 | H5: NUMERARIOS | J5: 4
A6: 6 | B6: 52 | D6: 1.1.01.01.0001 | I6: Caixa - Igreja | J6: 5 | K6: Disponibilidades | L6: X
A7: 7 | B7: 14019 | D7: 1.1.01.01.0002 | I7: Caixa - Cozinha | J7: 5 | K7: Disponibilidades | L7: X
A8: 8 | B8: 14061 | D8: 1.1.01.01.0003 | I8: Caixa - Bookafe | J8: 5 | K8: Disponibilidades | L8: X
A9: 9 | B9: 14077 | D9: 1.1.01.01.0004 | I9: Caixa - Literatura | J9: 5 | K9: Disponibilidades | L9: X
A10: 10 | B10: 14078 | D10: 1.1.01.01.0005 | I10: Caixa - Oferta Compromisso | J10: 5 | K10: Disponibilidades | L10: X
A11: 11 | B11: 5983 | D11: 1.1.01.01.0006 | I11: Caixa - Obra Regional | J11: 5 | K11: Disponibilidades | L11: X
A12: 12 | B12: 69 | C12: S | D12: 1.1.01.02 | H12: BANCOS C/ MOVIMENTO | J12: 4
A13: 13 | B13: 9082 | D13: 1.1.01.02.0001 | I13: Bradesco c/c 420-0 - Normal | J13: 5 | K13: Disponibilidades | L13: X
A14: 14 | B14: 9099 | D14: 1.1.01.02.0002 | I14: Bradesco c/c 430-8 - Conferencias | J14: 5 | K14: Disponibilidades | L14: X
A15: 15 | B15: 9100 | D15: 1.1.01.02.0003 | I15: Sicoob c/c 3314310-2 | J15: 5 | K15: Disponibilidades | L15: X
A16: 16 | B16: 9076 | D16: 1.1.01.02.0007 | I16: Bradesco c/c 440-5 - Novo Local | J16: 5 | K16: Disponibilidades | L16: X
A17: 17 | B17: 11392 | D17: 1.1.01.02.0010 | I17: Bradesco c/c 450-2 - Obra Regional | J17: 5 | K17: Disponibilidades | L17: X
A18: 18 | B18: 75 | C18: S | D18: 1.1.01.03 | H18: APLICACOES LIQUIDEZ IMEDIATA | J18: 4
A19: 19 | B19: 11699 | D19: 1.1.01.03.0001 | I19: Renda Fixa Saturno - 420-0 | J19: 5 | K19: Disponibilidades | L19: X
A20: 20 | B20: 9509 | D20: 1.1.01.03.0002 | I20: Renda Fixa CCDI - 430-8 | J20: 5 | K20: Disponibilidades | L20: X
A21: 21 | B21: 7901 | D21: 1.1.01.03.0003 | I21: Bradesco FIC RF Saturno - 440-5 | J21: 5 | K21: Disponibilidades | L21: X
A22: 22 | B22: 12799 | D22: 1.1.01.03.0004 | I22: Renda Fixa Saturno conta 450-2 | J22: 5 | K22: Disponibilidades | L22: X
A23: 23 | B23: 7902 | D23: 1.1.01.03.0005 | I23: Aplicacao Financeira - Sicoob | J23: 5 | K23: Disponibilidades | L23: X
A24: 24 | B24: 81 | C24: S | D24: 1.1.02 | G24: VALORES A RECEBER | J24: 3
A25: 25 | B25: 98 | C25: S | D25: 1.1.02.01 | H25: EMPRESTIMOS CONCEDIDOS | J25: 4
A26: 26 | B26: 13860 | D26: 1.1.02.01.0001 | I26: Alexandre Carlos Pereira | J26: 5 | K26: Disponibilidades | L26: X
A27: 27 | B27: 101 | D27: 1.1.02.01.0002 | I27: Edilson Geraldo de Assis | J27: 5 | K27: Disponibilidades | L27: X
A28: 28 | B28: 102 | D28: 1.1.02.01.0003 | I28: Maria das Gracas Monferrari | J28: 5 | K28: Disponibilidades | L28: X
A29: 29 | B29: 103 | D29: 1.1.02.01.0004 | I29: Maria Cecilia Monferrari da Costa | J29: 5 | K29: Disponibilidades | L29: X
A30: 30 | B30: 104 | D30: 1.1.02.01.0005 | I30: Joao Quirino | J30: 5 | K30: Disponibilidades | L30: X
A31: 31 | B31: 106 | D31: 1.1.02.01.0006 | I31: Mauricio Flaviano | J31: 5 | K31: Disponibilidades | L31: X
A32: 32 | B32: 108 | D32: 1.1.02.01.0043 | I32: Daniel Mateus Duarte | J32: 5 | K32: Disponibilidades | L32: X
A33: 33 | B33: 175 | D33: 1.1.02.01.0044 | I33: Agenor Braga Junior | J33: 5 | K33: Disponibilidades | L33: X
A34: 34 | B34: 174 | D34: 1.1.02.01.0045 | I34: Willian Ferreira Santos | J34: 5 | K34: Contas Patrimoniais | L34: 1 | M34: Adiantamentos e Emprestimos | N34: Willian Ferreira Santos
A35: 35 | B35: 14025 | D35: 1.1.02.01.0040 | I35: Fernando Claudio Neves | J35: 5 | K35: Contas Patrimoniais | L35: 1 | M35: Adiantamentos e Emprestimos | N35: Fernando Claudio Neves
A36: 36 | B36: 8071 | C36: S | D36: 1.1.02.99 | H36: OUTROS VALORES A RECEBER | J36: 4
A37: 37 | B37: 13942 | D37: 1.1.02.99.0001 | I37: Bookafe - Casa 01 | J37: 5 | K37: Contas Patrimoniais | L37: 1 | M37: Bookafe | N37: Bookafe - Casa 01
A38: 38 | B38: 13965 | D38: 1.1.02.99.0003 | I38: Bookafe - Casa 03 | J38: 5 | K38: Contas Patrimoniais | L38: 1 | M38: Bookafe | N38: Bookafe - Casa 03
A39: 39 | B39: 13959 | D39: 1.1.02.99.0004 | I39: Bookafe - Casa 04 | J39: 5 | K39: Contas Patrimoniais | L39: 1 | M39: Bookafe | N39: Bookafe - Casa 04
A40: 40 | B40: 13971 | D40: 1.1.02.99.0011 | I40: Bookafe - Casa 11 | J40: 5 | K40: Contas Patrimoniais | L40: 1 | M40: Bookafe | N40: Bookafe - Casa 11
...

Sheet Plano.Vinculacao_Conta.Azul
A1: Descricao da Conta | B1: Cód Vinculação
A2: 13º salario | B2: 218 | C2: =IF(A2=A1,"X","")
A3: Adiantamento de Salario | B3: 193 | C3: =IF(A3=A2,"X","")
A4: Agua, Luz e Telefone (Casa 1) | B4: 5581 | C4: =IF(A4=A3,"X","")
A5: Agua, Luz e Telefone (Casa 2) | B5: 5501 | C5: =IF(A5=A4,"X","")
A6: Alimentacao de Empregados | B6: 5121 | C6: =IF(A6=A5,"X","")
A7: Alimentacao e Refeitorio | B7: 8020 | C7: =IF(A7=A6,"X","")
A8: Aluguel de Bens Moveis - Conferencia | B8: 8384 | C8: =IF(A8=A7,"X","")
A9: Aluguel de Imoveis - Conferencia | B9: 8378 | C9: =IF(A9=A8,"X","")
A10: Aluguel do Auditorio | B10: 12604 | C10: =IF(A10=A9,"X","")
A11: Aluguel, Iptu, Seguro e Taxas (Casa 2) | B11: 5517 | C11: =IF(A11=A10,"X","")
A12: Aparelhos e Equipamentos | B12: 721 | C12: =IF(A12=A11,"X","")
A13: Aplicativos e Internet | B13: 7769 | C13: =IF(A13=A12,"X","")
... A15: Assistencia Medica e Odontologica | B15: 5138 | C15: =IF(A15=A14,"X","")
A16: Associacao Arvore da Vida - Emprestimo | B16: 178
A17: Auxilio p/ Africa | B17: 6037 | C17: =IF(A17=A16,"X","")
A18: Auxilio p/ Irmaos Necessitados | B18: 4802 | C18: =IF(A18=A17,"X","")
A19: Auxilio p/ Tempo Integral e Colportagem | B19: 4819 | C19: =IF(A19=A18,"X","")
A20: Benfeitorias em Imoveis de Terceiros | B20: 8237 | C20: =IF(A20=A19,"X","")
A21: Bookafe Casa 01 - Compras e Mao de Obra | B21: 12629 | C21: =IF(A21=A20,"X","")
A22: CEAPE | B22: 11593 | C22: =IF(A22=A21,"X","")
A23: Combustivel a Servico da Igreja | B23: 5180 | C23: =IF(A23=A22,"X","")
A24: Combustivel e Locomocao - Conferencia | B24: 8467 | C24: =IF(A24=A23,"X","")
A25: Conducao e Transporte | B25: 5211 | C25: =IF(A25=A24,"X","")
A26: Conserto e Manutencao Equipamentos | B26: 5693 | C26: =IF(A26=A25,"X","")
A27: Copias, Registros e Autenticacoes | B27: 5671 | C27: =IF(A27=A26,"X","")
A28: Correios e Malotes | B28: 5196 | C28: =IF(A28=A27,"X","")
... A30: Descontos Obtidos | B30: 4713 | C30: =IF(A30=A29,"X","")
A31: Despesas Bancarias | B31: 5279
A32: Despesas de Cobranca | B32: 7982 | C32: =IF(A32=A31,"X","")
A33: Despesas Diversas | B33: 5240 | C33: =IF(A33=A32,"X","")
A34: Devolucoes de Dizimos e Ofertas | B34: 4529
A35: Distribuidora e Livraria Manancial Ltda | B35: 173 | C35: =IF(A35=A34,"X","")
A36: Dizimos | B36: 4529 | C36: =IF(A36=A35,"X","")
A37: Edificacoes | B37: 691 | C37: =IF(A37=A36,"X","")
A38: Equipamentos de Informatica | B38: 9403 | C38: =IF(A38=A37,"X","")
A39: Estacionamento (Casa 1) | B39: 5613
A40: Estancia Arvore da Vida | B40: 7717 | C40: =IF(A40=A39,"X","")
A41: Ferias | B41: 201 | C41: =IF(A41=A40,"X","")
A42: Fernando Claudio Neves - Emprestimo | B42: 14025
...

Sheet TD_Plano.Contas
A1: Descricao da Conta | B1: Conta | C1: Cod.Reduzido | D1: Codigo | E1: Grupo de Contas 1 | F1: Cod Grupo 1 | G1: Grupo de Contas 2
A2: =IFERROR(INDEX('Plano.Vinculacao_Conta.Azul'!$A$1:$B$168,MATCH(Tabela4[[#This Row],[Cod.Reduzido]],'Plano.Vinculacao_Conta.Azul'!$B$1:$B$168,0),MATCH(A$1,'Plano.Vinculacao_Conta.Azul'!$A$1:$B$1,0)),"") -> 13º salario | B2: 13º Salario | C2: 218 | D2: 1.1.03.03.0003 | E2: Despesas Administrativas | F2: 7 | G2: Trabalhistas
A3: =IFERROR(INDEX('Plano.Vinculacao_Conta.Azul'!$A$1:$B$168,MATCH(Tabela4[[#This Row],[Cod.Reduzido]],'Plano.Vinculacao_Conta.Azul'!$B$1:$B$168,0),MATCH(A$1,'Plano.Vinculacao_Conta.Azul'!$A$1:$B$1,0)),"") | B3: 13º Salario | C3: 5091 | D3: 3.2.01.02.0003 | E3: Despesas Administrativas | F3: 7 | G3: Trabalhistas
A4: =IFERROR(INDEX('Plano.Vinculacao_Conta.Azul'!$A$1:$B$168,MATCH(Tabela4[[#This Row],[Cod.Reduzido]],'Plano.Vinculacao_Conta.Azul'!$B$1:$B$168,0),MATCH(A$1,'Plano.Vinculacao_Conta.Azul'!$A$1:$B$1,0)),"") -> Agua, Luz e Telefone (Casa 1) | B4: Agua, Luz e Telefone | C4: 5581 | D4: 3.2.02.01.0001 | E4: Casas de Reunioes | F4: 5 | G4: Casa 01
A5: =IFERROR(INDEX('Plano.Vinculacao_Conta.Azul'!$A$1:$B$168,MATCH(Tabela4[[#This Row],[Cod.Reduzido]],'Plano.Vinculacao_Conta.Azul'!$B$1:$B$168,0),MATCH(A$1,'Plano.Vinculacao_Conta.Azul'!$A$1:$B$1,0)),"") -> Agua, Luz e Telefone (Casa 2) | B5: Agua, Luz e Telefone | C5: 5501 | D5: 3.2.02.02.0001 | E5: Casas de Reunioes | F5: 5 | G5: Casa 02
A6: =IFERROR(INDEX('Plano.Vinculacao_Conta.Azul'!$A$1:$B$168,MATCH(Tabela4[[#This Row],[Cod.Reduzido]],'Plano.Vinculacao_Conta.Azul'!$B$1:$B$168,0),MATCH(A$1,'Plano.Vinculacao_Conta.Azul'!$A$1:$B$1,0)),"") | B6: Agua, Luz e Telefone | C6: 5546 | D6: 3.2.02.03.0001 | E6: Casas de Reunioes | F6: 5 | G6: Casa 03
A7: =IFERROR(INDEX('Plano.Vinculacao_Conta.Azul'!$A$1:$B$168,MATCH(Tabela4[[#This Row],[Cod.Reduzido]],'Plano.Vinculacao_Conta.Azul'!$B$1:$B$168,0),MATCH(A$1,'Plano.Vinculacao_Conta.Azul'!$A$1:$B$1,0)),"") | B7: Agua, Luz e Telefone | C7: 5629 | D7: 3.2.02.04.0001 | E7: Casas de Reunioes | F7: 5 | G7: Casa 04
A8: =IFERROR(INDEX('Plano.Vinculacao_Conta.Azul'!$A$1:$B$168,MATCH(Tabela4[[#This Row],[Cod.Reduzido]],'Plano.Vinculacao_Conta.Azul'!$B$1:$B$168,0),MATCH(A$1,'Plano.Vinculacao_Conta.Azul'!$A$1:$B$1,0)),"") | B8: Agua, Luz e Telefone | C8: 10056 | D8: 3.2.02.05.0001 | E8: Casas de Reunioes | F8: 5 | G8: Casa 05
A9: =IFERROR(INDEX('Plano.Vinculacao_Conta.Azul'!$A$1:$B$168,MATCH(Tabela4[[#This Row],[Cod.Reduzido]],'Plano.Vinculacao_Conta.Azul'!$B$1:$B$168,0),MATCH(A$1,'Plano.Vinculacao_Conta.Azul'!$A$1:$B$1,0)),"") | B9: Agua, Luz e Telefone | C9: 10100 | D9: 3.2.02.06.0001 | E9: Casas de Reunioes | F9: 5 | G9: Casa 06
A10: =IFERROR(INDEX('Plano.Vinculacao_Conta.Azul'!$A$1:$B$168,MATCH(Tabela4[[#This Row],[Cod.Reduzido]],'Plano.Vinculacao_Conta.Azul'!$B$1:$B$168,0),MATCH(A$1,'Plano.Vinculacao_Conta.Azul'!$A$1:$B$1,0)),"") | B10: Agua, Luz e Telefone | C10: 10151 | D10: 3.2.02.07.0001 | E10: Casas de Reunioes | F10: 5 | G10: Casa 07
A11: =IFERROR(INDEX('Plano.Vinculacao_Conta.Azul'!$A$1:$B$168,MATCH(Tabela4[[#This Row],[Cod.Reduzido]],'Plano.Vinculacao_Conta.Azul'!$B$1:$B$168,0),MATCH(A$1,'Plano.Vinculacao_Conta.Azul'!$A$1:$B$1,0)),"") | B11: Agua, Luz e Telefone | C11: 10205 | D11: 3.2.02.08.0001 | E11: Casas de Reunioes | F11: 5 | G11: Casa 08
A12: =IFERROR(INDEX('Plano.Vinculacao_Conta.Azul'!$A$1:$B$168,MATCH(Tabela4[[#This Row],[Cod.Reduzido]],'Plano.Vinculacao_Conta.Azul'!$B$1:$B$168,0),MATCH(A$1,'Plano.Vinculacao_Conta.Azul'!$A$1:$B$1,0)),"") | B12: Agua, Luz e Telefone | C12: 11788 | D12: 3.2.02.09.0001 | E12: Casas de Reunioes | F12: 5 | G12: Casa 09
A13: =IFERROR(INDEX('Plano.Vinculacao_Conta.Azul'!$A$1:$B$168,MATCH(Tabela4[[#This Row],[Cod.Reduzido]],'Plano.Vinculacao_Conta.Azul'!$B$1:$B$168,0),MATCH(A$1,'Plano.Vinculacao_Conta.Azul'!$A$1:$B$1,0)),"") | B13: Agua, Luz e Telefone | C13: 11794 | D13: 3.2.02.10.0001 | E13: Casas de Reunioes | F13: 5 | G13: Casa 10
... A74: =IFERROR(INDEX('Plano.Vinculacao_Conta.Azul'!$A$1:$B$168,MATCH(Tabela4[[#This Row],[Cod.Reduzido]],'Plano.Vinculacao_Conta.Azul'!$B$1:$B$168,0),MATCH(A$1,'Plano.Vinculacao_Conta.Azul'!$A$1:$B$1,0)),"") -> Distribuidora e Livraria Manancial Ltda | B74: Distribuidora e Livraria Manancial Ltda | C74: 173 | D74: 2.1.02.01.0003 | E74: Contas Patrimoniais | F74: 1 | G74: Adiantamentos e Emprestimos
A75: Dizimos | B75: Dizimos | C75: 4529 | D75: 3.1.01.01.0001 | E75: Receitas de Ofertas | F75: 2 | G75: Receitas de Ofertas
A76: =IFERROR(INDEX('Plano.Vinculacao_Conta.Azul'!$A$1:$B$168,MATCH(Tabela4[[#This Row],[Cod.Reduzido]],'Plano.Vinculacao_Conta.Azul'!$B$1:$B$168,0),MATCH(A$1,'Plano.Vinculacao_Conta.Azul'!$A$1:$B$1,0)),"") | B76: Dizimos | C76: 8154 | D76: 3.1.01.03.0001 | E76: Receitas de Ofertas | F76: 2 | G76: Receitas de Ofertas
A77: =IFERROR(INDEX('Plano.Vinculacao_Conta.Azul'!$A$1:$B$168,MATCH(Tabela4[[#This Row],[Cod.Reduzido]],'Plano.Vinculacao_Conta.Azul'!$B$1:$B$168,0),MATCH(A$1,'Plano.Vinculacao_Conta.Azul'!$A$1:$B$1,0)),"") -> Edificacoes | B77: Edificacoes | C77: 691 | D77: 1.2.02.01.0002 | E77: Contas Patrimoniais | F77: 1 | G77: Bens Patrimoniais
A78: =IFERROR(INDEX('Plano.Vinculacao_Conta.Azul'!$A$1:$B$168,MATCH(Tabela4[[#This Row],[Cod.Reduzido]],'Plano.Vinculacao_Conta.Azul'!$B$1:$B$168,0),MATCH(A$1,'Plano.Vinculacao_Conta.Azul'!$A$1:$B$1,0)),"") | B78: Encargos Sociais | C78: 5109 | D78: 3.2.01.02.0004 | E78: Despesas Administrativas | F78: 7 | G78: Trabalhistas
A79: =IFERROR(INDEX('Plano.Vinculacao_Conta.Azul'!$A$1:$B$168,MATCH(Tabela4[[#This Row],[Cod.Reduzido]],'Plano.Vinculacao_Conta.Azul'!$B$1:$B$168,0),MATCH(A$1,'Plano.Vinculacao_Conta.Azul'!$A$1:$B$1,0)),"") -> Equipamentos de Informatica | B79: Equipamentos de Informatica | C79: 9403 | D79: 1.2.02.01.0008 | E79: Contas Patrimoniais | F79: 1 | G79: Bens Patrimoniais
A80: =IFERROR(INDEX('Plano.Vinculacao_Conta.Azul'!$A$1:$B$168,MATCH(Tabela4[[#This Row],[Cod.Reduzido]],'Plano.Vinculacao_Conta.Azul'!$B$1:$B$168,0),MATCH(A$1,'Plano.Vinculacao_Conta.Azul'!$A$1:$B$1,0)),"") -> Estancia Arvore da Vida | B80: Estancia Arvore da Vida | C80: 7717 | D80: 3.2.01.01.0019 | E80: Despesas Ministeriais | F80: 6 | G80: Despesas Ministeriais
A81: =IFERROR(INDEX('Plano.Vinculacao_Conta.Azul'!$A$1:$B$168,MATCH(Tabela4[[#This Row],[Cod.Reduzido]],'Plano.Vinculacao_Conta.Azul'!$B$1:$B$168,0),MATCH(A$1,'Plano.Vinculacao_Conta.Azul'!$A$1:$B$1,0)),"") -> Ferias | B81: Ferias | C81: 201 | D81: 1.1.03.03.0002 | E81: Despesas Administrativas | F81: 7 | G81: Trabalhistas
A82: =IFERROR(INDEX('Plano.Vinculacao_Conta.Azul'!$A$1:$B$168,MATCH(Tabela4[[#This Row],[Cod.Reduzido]],'Plano.Vinculacao_Conta.Azul'!$B$1:$B$168,0),MATCH(A$1,'Plano.Vinculacao_Conta.Azul'!$A$1:$B$1,0)),"") | B82: Ferias | C82: 5084 | D82: 3.2.01.02.0002 | E82: Despesas Administrativas | F82: 7 | G82: Trabalhistas
A83: =IFERROR(INDEX('Plano.Vinculacao_Conta.Azul'!$A$1:$B$168,MATCH(Tabela4[[#This Row],[Cod.Reduzido]],'Plano.Vinculacao_Conta.Azul'!$B$1:$B$168,0),MATCH(A$1,'Plano.Vinculacao_Conta.Azul'!$A$1:$B$1,0)),"") -> FGTS a Recolher | B83: FGTS a Recolher | C83: 1011 | D83: 2.1.03.02.0002 | E83: Despesas Administrativas | F83: 7 | G83: Encargos Sociais
A84: =IFERROR(INDEX('Plano.Vinculacao_Conta.Azul'!$A$1:$B$168,MATCH(Tabela4[[#This Row],[Cod.Reduzido]],'Plano.Vinculacao_Conta.Azul'!$B$1:$B$168,0),MATCH(A$1,'Plano.Vinculacao_Conta.Azul'!$A$1:$B$1,0)),"") -> Fretamento de Veiculos - Conferencia | B84: Fretamento de Veiculos | C84: 8391 | D84: 3.1.04.02.0003 | E84: Servico de Conferencias | F84: 4 | G84: Despesas de Conferencias
A85: =IFERROR(INDEX('Plano.Vinculacao_Conta.Azul'!$A$1:$B$168,MATCH(Tabela4[[#This Row],[Cod.Reduzido]],'Plano.Vinculacao_Conta.Azul'!$B$1:$B$168,0),MATCH(A$1,'Plano.Vinculacao_Conta.Azul'!$A$1:$B$1,0)),"") -> Gastos de Viagem p/ Israel | B85: Gastos de Viagem p/ Israel | C85: 13043 | D85: 3.2.01.01.0025 | E85: Despesas Ministeriais | F85: 6 | G85: Despesas Ministeriais
A86: =IFERROR(INDEX('Plano.Vinculacao_Conta.Azul'!$A$1:$B$168,MATCH(Tabela4[[#This Row],[Cod.Reduzido]],'Plano.Vinculacao_Conta.Azul'!$B$1:$B$168,0),MATCH(A$1,'Plano.Vinculacao_Conta.Azul'!$A$1:$B$1,0)),"") -> Higiene e Limpeza (Casa 1) | B86: Higiene e Limpeza | C86: 5612 | D86: 3.2.02.01.0004 | E86: Casas de Reunioes | F86: 5 | G86: Casa 01
A87: =IFERROR(INDEX('Plano.Vinculacao_Conta.Azul'!$A$1:$B$168,MATCH(Tabela4[[#This Row],[Cod.Reduzido]],'Plano.Vinculacao_Conta.Azul'!$B$1:$B$168,0),MATCH(A$1,'Plano.Vinculacao_Conta.Azul'!$A$1:$B$1,0)),"") -> Higiene e Limpeza (Casa 2) | B87: Higiene e Limpeza | C87: 5530 | D87: 3.2.02.02.0004 | E87: Casas de Reunioes | F87: 5 | G87: Casa 02
... A245: =IFERROR(INDEX('Plano.Vinculacao_Conta.Azul'!$A$1:$B$168,MATCH(Tabela4[[#This Row],[Cod.Reduzido]],'Plano.Vinculacao_Conta.Azul'!$B$1:$B$168,0),MATCH(A$1,'Plano.Vinculacao_Conta.Azul'!$A$1:$B$1,0)),"") -> Mauricio Flaviano Martins - Emprestimo | B245: Mauricio Flaviano Martins | C245: 106 | D245: 1.1.02.01.0006 | E245: Contas Patrimoniais | F245: 1 | G245: Adiantamentos e Emprestimos

Sheet TD_Fornecedores
A1: Codigo | B1: FORNECEDORES
A2: 1 | B2: FRAGA TUR LTDA
A3: 2 | B3: ACM DISTRIBUIDORA DE PROD ELETRO EIRELI - ME
A4: 3 | B4: ADICAO DISTRIBUICAO EXPRESS S/A
A5: 4 | B5: AGENCIA DO OLEO
A6: 5 | B6: AGEO AGROPECUARIA LTDA
A7: 6 | B7: AGUIA IV COMERCIO DE COMBUSTIVEIS LTDA
A8: 7 | B8: ALINE DE OLIVEIRA RIBEIRO DUARTE
A9: 8 | B9: AMERICANAS S/A
A10: 9 | B10: ANA CAROLINA SENA NEVES
A11: 10 | B11: ANA FERREIRA SILVA RODRIGUES
A12: 11 | B12: ANA MARGARIDA DE OLIVEIRA RODRIGUES - ME
A13: 12 | B13: ARENA ATACADO SUPERMERCADOS CAVICCHIULLI LTDA
... A262: 261 | B262: WMB SUPERMERCADOS DO BRASIL LTDA

Sheet TD_Centro.Custos
A1: Codigo | B1: CENTRO DE CUSTO
A2: 1 | B2: CONFERENCIA INTERNACIONAL
A3: 2 | B3: CONFERENCIA MICRORREGIONAL
A4: 3 | B4: CONGRESSO DE MULHERES
A5: 4 | B5: FABRICA DE VENCEDORES
A6: 5 | B6: MINISTERIO DE MULHERES
A7: 6 | B7: SERVICO DA MATURIDADE
A8: 7 | B8: SERVICO DE ADOLESCENTES
A9: 8 | B9: SERVICO DE CRIANCAS
A10: 9 | B10: SERVICO DE JOVENS - START
A11: 10 | B11: SERVICOS DA IGREJA

Sheet Grafico_2017
A1: ASSOCIAÇÃO DAS IGREJAS DA OBRA REGIONAL - REGIÃO 6
A2: Fluxo Financeiro - 2017
A4: Gráfico - Fluxo Financeiro 2016 | B4: Jan | C4: Fev | D4: Mar | E4: Abr | F4: Mai | G4: Jun | H4: Jul | I4: Ago | J4: Set | K4: Out | L4: Nov | M4: Dez | O4: Jan a Dez | P4: Média Mensal | Q4: %
B5: 2 | C5: 3 | D5: 4 | E5: 5 | F5: 6 | G5: 7 | H5: 8 | I5: 9 | J5: 10 | K5: 11 | L5: 12 | M5: 13
A6: Reuniao Aperfeicoamento - Alimentacao | B6: =VLOOKUP($A$6,Fluxo.Detalhado_2016!$A:$M,B5,0) -> #REF! | C6: =VLOOKUP($A$6,Fluxo.Detalhado_2016!$A:$M,C5,0) -> #REF! | D6: =VLOOKUP($A$6,Fluxo.Detalhado_2016!$A:$M,D5,0) -> #REF! | E6: =VLOOKUP($A$6,Fluxo.Detalhado_2016!$A:$M,E5,0) -> #REF! | F6: =VLOOKUP($A$6,Fluxo.Detalhado_2016!$A:$M,F5,0) -> #REF! | G6: =VLOOKUP($A$6,Fluxo.Detalhado_2016!$A:$M,G5,0) -> #REF! | H6: =VLOOKUP($A$6,Fluxo.Detalhado_2016!$A:$M,H5,0) -> #REF! | I6: =VLOOKUP($A$6,Fluxo.Detalhado_2016!$A:$M,I5,0) -> #REF! | ... M6: =VLOOKUP($A$6,Fluxo.Detalhado_2016!$A:$M,M5,0) -> #REF! | N6: =A6 -> Reuniao Aperfeicoamento - Alimentacao | O6: =SUM(B6:N6) -> #REF! | P6: =O6/12 -> #REF! | Q6: =O6/O7 -> #REF!
A7: =VLOOKUP(A6,Fluxo.Detalhado_2016!A:P,16,0) -> TOTAL DE COLPORTAGEM | B7: =VLOOKUP($A$7,Fluxo.Detalhado_2016!$A:$M,B5,0) -> #REF! | C7: =VLOOKUP($A$7,Fluxo.Detalhado_2016!$A:$M,C5,0) -> #REF! | D7: =VLOOKUP($A$7,Fluxo.Detalhado_2016!$A:$M,D5,0) -> #REF! | E7: =VLOOKUP($A$7,Fluxo.Detalhado_2016!$A:$M,E5,0) -> #REF! | F7: =VLOOKUP($A$7,Fluxo.Detalhado_2016!$A:$M,F5,0) -> #REF! | G7: =VLOOKUP($A$7,Fluxo.Detalhado_2016!$A:$M,G5,0) -> #REF! | H7: =VLOOKUP($A$7,Fluxo.Detalhado_2016!$A:$M,H5,0) -> #REF! | I7: =VLOOKUP($A$7,Fluxo.Detalhado_2016!$A:$M,I5,0) -> #REF! | ... M7: =VLOOKUP($A$7,Fluxo.Detalhado_2016!$A:$M,M5,0) -> #REF! | N7: =A7 -> TOTAL DE COLPORTAGEM | O7: =SUM(B7:N7) -> #REF! | P7: =O7/12 -> #REF! | Q7: 1
B8: 2 | C8: 3 | D8: 4 | E8: 5 | F8: 6 | G8: 7 | H8: 8 | I8: 9 | J8: 10 | K8: 11 | L8: 12 | M8: 13 | O8: 15

Sheet Fluxo.Detalhado_2016
A1: RELATÓRIO FINANCEIRO - 2016 | B1: Jan | C1: Fev | D1: Mar | E1: Abr | F1: Mai | G1: Jun | H1: Jul | I1: Ago | J1: Set | K1: Out | L1: Nov | M1: Dez | O1: Ano 2016
B2: 1 | C2: 2 | D2: 3 | E2: 4 | F2: 5 | G2: 6 | H2: 7 | I2: 8 | J2: 9 | K2: 10 | L2: 11 | M2: 12
A3: RECEITAS DE OFERTAS
A4: Ofertas Regulares | B4: =SUMIFS(#REF!,#REF!,$A4,#REF!,B$2) -> #REF! | C4: =SUMIFS(#REF!,#REF!,$A4,#REF!,C$2) -> #REF! | D4: =SUMIFS(#REF!,#REF!,$A4,#REF!,D$2) -> #REF! | E4: =SUMIFS(#REF!,#REF!,$A4,#REF!,E$2) -> #REF! | F4: =SUMIFS(#REF!,#REF!,$A4,#REF!,F$2) -> #REF! | G4: =SUMIFS(#REF!,#REF!,$A4,#REF!,G$2) -> #REF! | H4: =SUMIFS(#REF!,#REF!,$A4,#REF!,H$2) -> #REF! | I4: =SUMIFS(#REF!,#REF!,$A4,#REF!,I$2) -> #REF! | ... M4: =SUMIFS(#REF!,#REF!,$A4,#REF!,M$2) -> #REF! | O4: =SUM(B4:N4) -> #REF! | P4: TOTAL DAS ENTRADAS
A5: Ofertas p/ Africa/Angola e EUA | B5: =SUMIFS(#REF!,#REF!,$A5,#REF!,B$2) -> #REF! | C5: =SUMIFS(#REF!,#REF!,$A5,#REF!,C$2) -> #REF! | D5: =SUMIFS(#REF!,#REF!,$A5,#REF!,D$2) -> #REF! | E5: =SUMIFS(#REF!,#REF!,$A5,#REF!,E$2) -> #REF! | F5: =SUMIFS(#REF!,#REF!,$A5,#REF!,F$2) -> #REF! | G5: =SUMIFS(#REF!,#REF!,$A5,#REF!,G$2) -> #REF! | H5: =SUMIFS(#REF!,#REF!,$A5,#REF!,H$2) -> #REF! | I5: =SUMIFS(#REF!,#REF!,$A5,#REF!,I$2) -> #REF! | ... M5: =SUMIFS(#REF!,#REF!,$A5,#REF!,M$2) -> #REF! | O5: =SUM(B5:N5) -> #REF! | P5: TOTAL DAS ENTRADAS
A6: Ofertas p/ CEAPE | B6: =SUMIFS(#REF!,#REF!,$A6,#REF!,B$2) -> #REF! | C6: =SUMIFS(#REF!,#REF!,$A6,#REF!,C$2) -> #REF! | D6: =SUMIFS(#REF!,#REF!,$A6,#REF!,D$2) -> #REF! | E6: =SUMIFS(#REF!,#REF!,$A6,#REF!,E$2) -> #REF! | F6: =SUMIFS(#REF!,#REF!,$A6,#REF!,F$2) -> #REF! | G6: =SUMIFS(#REF!,#REF!,$A6,#REF!,G$2) -> #REF! | H6: =SUMIFS(#REF!,#REF!,$A6,#REF!,H$2) -> #REF! | I6: =SUMIFS(#REF!,#REF!,$A6,#REF!,I$2) -> #REF! | ... M6: =SUMIFS(#REF!,#REF!,$A6,#REF!,M$2) -> #REF! | O6: =SUM(B6:N6) -> #REF! | P6: TOTAL DAS ENTRADAS
A7: Ofertas Diversas | B7: =SUMIFS(#REF!,#REF!,$A7,#REF!,B$2) -> #REF! | C7: =SUMIFS(#REF!,#REF!,$A7,#REF!,C$2) -> #REF! | D7: =SUMIFS(#REF!,#REF!,$A7,#REF!,D$2) -> #REF! | E7: =SUMIFS(#REF!,#REF!,$A7,#REF!,E$2) -> #REF! | F7: =SUMIFS(#REF!,#REF!,$A7,#REF!,F$2) -> #REF! | G7: =SUMIFS(#REF!,#REF!,$A7,#REF!,G$2) -> #REF! | H7: =SUMIFS(#REF!,#REF!,$A7,#REF!,H$2) -> #REF! | I7: =SUMIFS(#REF!,#REF!,$A7,#REF!,I$2) -> #REF! | ... M7: =SUMIFS(#REF!,#REF!,$A7,#REF!,M$2) -> #REF! | O7: =SUM(B7:N7) -> #REF! | P7: TOTAL DAS ENTRADAS
A8: Total de Dizimos e Ofertas | B8: =SUM(B4:B7) -> #REF! | C8: =SUM(C4:C7) -> #REF! | D8: =SUM(D4:D7) -> #REF! | E8: =SUM(E4:E7) -> #REF! | F8: =SUM(F4:F7) -> #REF! | G8: =SUM(G4:G7) -> #REF! | H8: =SUM(H4:H7) -> #REF! | I8: =SUM(I4:I7) -> #REF! | ... M8: =SUM(M4:M7) -> #REF! | O8: =SUM(O4:O7) -> #REF! | P8: TOTAL DAS ENTRADAS
A9: OUTRAS RECEITAS
A10: Reembolso de Refeicoes | B10: =SUMIFS(#REF!,#REF!,$A10,#REF!,B$2) -> #REF! | C10: =SUMIFS(#REF!,#REF!,$A10,#REF!,C$2) -> #REF! | D10: =SUMIFS(#REF!,#REF!,$A10,#REF!,D$2) -> #REF! | E10: =SUMIFS(#REF!,#REF!,$A10,#REF!,E$2) -> #REF! | F10: =SUMIFS(#REF!,#REF!,$A10,#REF!,F$2) -> #REF! | G10: =SUMIFS(#REF!,#REF!,$A10,#REF!,G$2) -> #REF! | H10: =SUMIFS(#REF!,#REF!,$A10,#REF!,H$2) -> #REF! | I10: =SUMIFS(#REF!,#REF!,$A10,#REF!,I$2) -> #REF! | ... M10: =SUMIFS(#REF!,#REF!,$A10,#REF!,M$2) -> #REF! | O10: =SUM(B10:N10) -> #REF! | P10: TOTAL DAS ENTRADAS
A11: CD's de mensagem | B11: =SUMIFS(#REF!,#REF!,$A11,#REF!,B$2) -> #REF! | C11: =SUMIFS(#REF!,#REF!,$A11,#REF!,C$2) -> #REF! | D11: =SUMIFS(#REF!,#REF!,$A11,#REF!,D$2) -> #REF! | E11: =SUMIFS(#REF!,#REF!,$A11,#REF!,E$2) -> #REF! | F11: =SUMIFS(#REF!,#REF!,$A11,#REF!,F$2) -> #REF! | G11: =SUMIFS(#REF!,#REF!,$A11,#REF!,G$2) -> #REF! | H11: =SUMIFS(#REF!,#REF!,$A11,#REF!,H$2) -> #REF! | I11: =SUMIFS(#REF!,#REF!,$A11,#REF!,I$2) -> #REF! | ... M11: =SUMIFS(#REF!,#REF!,$A11,#REF!,M$2) -> #REF! | O11: =SUM(B11:N11) -> #REF! | P11: TOTAL DAS ENTRADAS
A12: Reembolso de Encontro de Obreiros | B12: =SUMIFS(#REF!,#REF!,$A12,#REF!,B$2) -> #REF! | C12: =SUMIFS(#REF!,#REF!,$A12,#REF!,C$2) -> #REF! | D12: =SUMIFS(#REF!,#REF!,$A12,#REF!,D$2) -> #REF! | E12: =SUMIFS(#REF!,#REF!,$A12,#REF!,E$2) -> #REF! | F12: =SUMIFS(#REF!,#REF!,$A12,#REF!,F$2) -> #REF! | G12: =SUMIFS(#REF!,#REF!,$A12,#REF!,G$2) -> #REF! | H12: =SUMIFS(#REF!,#REF!,$A12,#REF!,H$2) -> #REF! | I12: =SUMIFS(#REF!,#REF!,$A12,#REF!,I$2) -> #REF! | ... M12: =SUMIFS(#REF!,#REF!,$A12,#REF!,M$2) -> #REF! | O12: =SUM(B12:N12) -> #REF! | P12: TOTAL DAS ENTRADAS
A13: Rendimentos de Aplicacoes Financeiras | B13: =SUMIFS(#REF!,#REF!,$A13,#REF!,B$2) -> #REF! | C13: =SUMIFS(#REF!,#REF!,$A13,#REF!,C$2) -> #REF! | D13: =SUMIFS(#REF!,#REF!,$A13,#REF!,D$2) -> #REF! | E13: =SUMIFS(#REF!,#REF!,$A13,#REF!,E$2) -> #REF! | F13: =SUMIFS(#REF!,#REF!,$A13,#REF!,F$2) -> #REF! | G13: =SUMIFS(#REF!,#REF!,$A13,#REF!,G$2) -> #REF! | H13: =SUMIFS(#REF!,#REF!,$A13,#REF!,H$2) -> #REF! | I13: =SUMIFS(#REF!,#REF!,$A13,#REF!,I$2) -> #REF! | ... M13: =SUMIFS(#REF!,#REF!,$A13,#REF!,M$2) -> #REF! | O13: =SUM(B13:N13) -> #REF! | P13: TOTAL DAS ENTRADAS
A14: Total de Outras Receitas | B14: =SUM(B10:B13) -> #REF! | C14: =SUM(C10:C13) -> #REF! | D14: =SUM(D10:D13) -> #REF! | E14: =SUM(E10:E13) -> #REF! | F14: =SUM(F10:F13) -> #REF! | G14: =SUM(G10:G13) -> #REF! | H14: =SUM(H10:H13) -> #REF! | I14: =SUM(I10:I13) -> #REF! | ... M14: =SUM(M10:M13) -> #REF! | O14: =SUM(O10:O13) -> #REF! | P14: TOTAL DAS ENTRADAS
A16: TOTAL DAS ENTRADAS | B16: =B8+B14 -> #REF! | C16: =C8+C14 -> #REF! | D16: =D8+D14 -> #REF! | E16: =E8+E14 -> #REF! | F16: =F8+F14 -> #REF! | G16: =G8+G14 -> #REF! | H16: =H8+H14 -> #REF! | I16: =I8+I14 -> #REF! | ... M16: =M8+M14 -> #REF! | O16: =O8+O14 -> #REF! | P16: TOTAL DAS ENTRADAS
A18: COLPORTAGEM
A19: Premiacao Mensal - Colportores | B19: =-SUMIFS(#REF!,#REF!,$A19,#REF!,B$2) -> #REF! | C19: =-SUMIFS(#REF!,#REF!,$A19,#REF!,C$2) -> #REF! | D19: =-SUMIFS(#REF!,#REF!,$A19,#REF!,D$2) -> #REF! | E19: =-SUMIFS(#REF!,#REF!,$A19,#REF!,E$2) -> #REF! | F19: =-SUMIFS(#REF!,#REF!,$A19,#REF!,F$2) -> #REF! | G19: =-SUMIFS(#REF!,#REF!,$A19,#REF!,G$2) -> #REF! | H19: =-SUMIFS(#REF!,#REF!,$A19,#REF!,H$2) -> #REF! | I19: =-SUMIFS(#REF!,#REF!,$A19,#REF!,I$2) -> #REF! | ... M19: =-SUMIFS(#REF!,#REF!,$A19,#REF!,M$2) -> #REF! | O19: =SUM(B19:N19) -> #REF! | P19: TOTAL DE COLPORTAGEM
A20: Aluguel de Colportores | B20: =-SUMIFS(#REF!,#REF!,$A20,#REF!,B$2) -> #REF! | C20: =-SUMIFS(#REF!,#REF!,$A20,#REF!,C$2) -> #REF! | D20: =-SUMIFS(#REF!,#REF!,$A20,#REF!,D$2) -> #REF! | E20: =-SUMIFS(#REF!,#REF!,$A20,#REF!,E$2) -> #REF! | F20: =-SUMIFS(#REF!,#REF!,$A20,#REF!,F$2) -> #REF! | G20: =-SUMIFS(#REF!,#REF!,$A20,#REF!,G$2) -> #REF! | H20: =-SUMIFS(#REF!,#REF!,$A20,#REF!,H$2) -> #REF! | I20: =-SUMIFS(#REF!,#REF!,$A20,#REF!,I$2) -> #REF! | ... M20: =-SUMIFS(#REF!,#REF!,$A20,#REF!,M$2) -> #REF! | O20: =SUM(B20:N20) -> #REF! | P20: TOTAL DE COLPORTAGEM
A21: Ofertas Adicionais - Colportores | B21: =-SUMIFS(#REF!,#REF!,$A21,#REF!,B$2) -> #REF! | C21: =-SUMIFS(#REF!,#REF!,$A21,#REF!,C$2) -> #REF! | D21: =-SUMIFS(#REF!,#REF!,$A21,#REF!,D$2) -> #REF! | E21: =-SUMIFS(#REF!,#REF!,$A21,#REF!,E$2) -> #REF! | F21: =-SUMIFS(#REF!,#REF!,$A21,#REF!,F$2) -> #REF! | G21: =-SUMIFS(#REF!,#REF!,$A21,#REF!,G$2) -> #REF! | H21: =-SUMIFS(#REF!,#REF!,$A21,#REF!,H$2) -> #REF! | I21: =-SUMIFS(#REF!,#REF!,$A21,#REF!,I$2) -> #REF! | ... M21: =-SUMIFS(#REF!,#REF!,$A21,#REF!,M$2) -> #REF! | O21: =SUM(B21:N21) -> #REF! | P21: TOTAL DE COLPORTAGEM
A22: Oferta em Livros - Colportores | B22: =-SUMIFS(#REF!,#REF!,$A22,#REF!,B$2) -> #REF! | C22: =-SUMIFS(#REF!,#REF!,$A22,#REF!,C$2) -> #REF! | D22: =-SUMIFS(#REF!,#REF!,$A22,#REF!,D$2) -> #REF! | E22: =-SUMIFS(#REF!,#REF!,$A22,#REF!,E$2) -> #REF! | F22: =-SUMIFS(#REF!,#REF!,$A22,#REF!,F$2) -> #REF! | G22: =-SUMIFS(#REF!,#REF!,$A22,#REF!,G$2) -> #REF! | H22: =-SUMIFS(#REF!,#REF!,$A22,#REF!,H$2) -> #REF! | I22: =-SUMIFS(#REF!,#REF!,$A22,#REF!,I$2) -> #REF! | ... M22: =-SUMIFS(#REF!,#REF!,$A22,#REF!,M$2) -> #REF! | O22: =SUM(B22:N22) -> #REF! | P22: TOTAL DE COLPORTAGEM
A23: Viagens na Colportagem | B23: =-SUMIFS(#REF!,#REF!,$A23,#REF!,B$2) -> #REF! | C23: =-SUMIFS(#REF!,#REF!,$A23,#REF!,C$2) -> #REF! | D23: =-SUMIFS(#REF!,#REF!,$A23,#REF!,D$2) -> #REF! | E23: =-SUMIFS(#REF!,#REF!,$A23,#REF!,E$2) -> #REF! | F23: =-SUMIFS(#REF!,#REF!,$A23,#REF!,F$2) -> #REF! | G23: =-SUMIFS(#REF!,#REF!,$A23,#REF!,G$2) -> #REF! | H23: =-SUMIFS(#REF!,#REF!,$A23,#REF!,H$2) -> #REF! | I23: =-SUMIFS(#REF!,#REF!,$A23,#REF!,I$2) -> #REF! | ... M23: =-SUMIFS(#REF!,#REF!,$A23,#REF!,M$2) -> #REF! | O23: =SUM(B23:N23) -> #REF! | P23: TOTAL DE COLPORTAGEM
A24: Reuniao Aperfeicoamento - Alimentacao | B24: =-SUMIFS(#REF!,#REF!,$A24,#REF!,B$2) -> #REF! | C24: =-SUMIFS(#REF!,#REF!,$A24,#REF!,C$2) -> #REF! | D24: =-SUMIFS(#REF!,#REF!,$A24,#REF!,D$2) -> #REF! | E24: =-SUMIFS(#REF!,#REF!,$A24,#REF!,E$2) -> #REF! | F24: =-SUMIFS(#REF!,#REF!,$A24,#REF!,F$2) -> #REF! | G24: =-SUMIFS(#REF!,#REF!,$A24,#REF!,G$2) -> #REF! | H24: =-SUMIFS(#REF!,#REF!,$A24,#REF!,H$2) -> #REF! | I24: =-SUMIFS(#REF!,#REF!,$A24,#REF!,I$2) -> #REF! | ... M24: =-SUMIFS(#REF!,#REF!,$A24,#REF!,M$2) -> #REF! | O24: =SUM(B24:N24) -> #REF! | P24: TOTAL DE COLPORTAGEM
A25: Reuniao Aperfeicoamento - Cozinha e Limpeza | B25: =-SUMIFS(#REF!,#REF!,$A25,#REF!,B$2) -> #REF! | C25: =-SUMIFS(#REF!,#REF!,$A25,#REF!,C$2) -> #REF! | D25: =-SUMIFS(#REF!,#REF!,$A25,#REF!,D$2) -> #REF! | E25: =-SUMIFS(#REF!,#REF!,$A25,#REF!,E$2) -> #REF! | F25: =-SUMIFS(#REF!,#REF!,$A25,#REF!,F$2) -> #REF! | G25: =-SUMIFS(#REF!,#REF!,$A25,#REF!,G$2) -> #REF! | H25: =-SUMIFS(#REF!,#REF!,$A25,#REF!,H$2) -> #REF! | I25: =-SUMIFS(#REF!,#REF!,$A25,#REF!,I$2) -> #REF! | ... M25: =-SUMIFS(#REF!,#REF!,$A25,#REF!,M$2) -> #REF! | O25: =SUM(B25:N25) -> #REF! | P25: TOTAL DE COLPORTAGEM
A26: Reuniao Aperfeicoamento - Copias e Xerox | B26: =-SUMIFS(#REF!,#REF!,$A26,#REF!,B$2) -> #REF! | C26: =-SUMIFS(#REF!,#REF!,$A26,#REF!,C$2) -> #REF! | D26: =-SUMIFS(#REF!,#REF!,$A26,#REF!,D$2) -> #REF! | E26: =-SUMIFS(#REF!,#REF!,$A26,#REF!,E$2) -> #REF! | F26: =-SUMIFS(#REF!,#REF!,$A26,#REF!,F$2) -> #REF! | G26: =-SUMIFS(#REF!,#REF!,$A26,#REF!,G$2) -> #REF! | H26: =-SUMIFS(#REF!,#REF!,$A26,#REF!,H$2) -> #REF! | I26: =-SUMIFS(#REF!,#REF!,$A26,#REF!,I$2) -> #REF! | ... M26: =-SUMIFS(#REF!,#REF!,$A26,#REF!,M$2) -> #REF! | O26: =SUM(B26:N26) -> #REF! | P26: TOTAL DE COLPORTAGEM
A27: Manutencao de Veiculos - Colportores | B27: =-SUMIFS(#REF!,#REF!,$A27,#REF!,B$2) -> #REF! | C27: =-SUMIFS(#REF!,#REF!,$A27,#REF!,C$2) -> #REF! | D27: =-SUMIFS(#REF!,#REF!,$A27,#REF!,D$2) -> #REF! | E27: =-SUMIFS(#REF!,#REF!,$A27,#REF!,E$2) -> #REF! | F27: =-SUMIFS(#REF!,#REF!,$A27,#REF!,F$2) -> #REF! | G27: =-SUMIFS(#REF!,#REF!,$A27,#REF!,G$2) -> #REF! | H27: =-SUMIFS(#REF!,#REF!,$A27,#REF!,H$2) -> #REF! | I27: =-SUMIFS(#REF!,#REF!,$A27,#REF!,I$2) -> #REF! | ... M27: =-SUMIFS(#REF!,#REF!,$A27,#REF!,M$2) -> #REF! | O27: =SUM(B27:N27) -> #REF! | P27: TOTAL DE COLPORTAGEM
A28: Aperfeicoamento de Colportores - Regiao 06 | B28: =-SUMIFS(#REF!,#REF!,$A28,#REF!,B$2) -> #REF! | C28: =-SUMIFS(#REF!,#REF!,$A28,#REF!,C$2) -> #REF! | D28: =-SUMIFS(#REF!,#REF!,$A28,#REF!,D$2) -> #REF! | E28: =-SUMIFS(#REF!,#REF!,$A28,#REF!,E$2) -> #REF! | F28: =-SUMIFS(#REF!,#REF!,$A28,#REF!,F$2) -> #REF! | G28: =-SUMIFS(#REF!,#REF!,$A28,#REF!,G$2) -> #REF! | H28: =-SUMIFS(#REF!,#REF!,$A28,#REF!,H$2) -> #REF! | I28: =-SUMIFS(#REF!,#REF!,$A28,#REF!,I$2) -> #REF! | ... M28: =-SUMIFS(#REF!,#REF!,$A28,#REF!,M$2) -> #REF! | O28: =SUM(B28:N28) -> #REF! | P28: TOTAL DE COLPORTAGEM
A29: Mudanca de Colportores - Migracao | B29: =-SUMIFS(#REF!,#REF!,$A29,#REF!,B$2) -> #REF! | C29: =-SUMIFS(#REF!,#REF!,$A29,#REF!,C$2) -> #REF! | D29: =-SUMIFS(#REF!,#REF!,$A29,#REF!,D$2) -> #REF! | E29: =-SUMIFS(#REF!,#REF!,$A29,#REF!,E$2) -> #REF! | F29: =-SUMIFS(#REF!,#REF!,$A29,#REF!,F$2) -> #REF! | G29: =-SUMIFS(#REF!,#REF!,$A29,#REF!,G$2) -> #REF! | H29: =-SUMIFS(#REF!,#REF!,$A29,#REF!,H$2) -> #REF! | I29: =-SUMIFS(#REF!,#REF!,$A29,#REF!,I$2) -> #REF! | ... M29: =-SUMIFS(#REF!,#REF!,$A29,#REF!,M$2) -> #REF! | O29: =SUM(B29:N29) -> #REF! | P29: TOTAL DE COLPORTAGEM
A30: Assistencia Medica e Odontologica - Colportores | B30: =-SUMIFS(#REF!,#REF!,$A30,#REF!,B$2) -> #REF! | C30: =-SUMIFS(#REF!,#REF!,$A30,#REF!,C$2) -> #REF! | D30: =-SUMIFS(#REF!,#REF!,$A30,#REF!,D$2) -> #REF! | E30: =-SUMIFS(#REF!,#REF!,$A30,#REF!,E$2) -> #REF! | F30: =-SUMIFS(#REF!,#REF!,$A30,#REF!,F$2) -> #REF! | G30: =-SUMIFS(#REF!,#REF!,$A30,#REF!,G$2) -> #REF! | H30: =-SUMIFS(#REF!,#REF!,$A30,#REF!,H$2) -> #REF! | I30: =-SUMIFS(#REF!,#REF!,$A30,#REF!,I$2) -> #REF! | ... M30: =-SUMIFS(#REF!,#REF!,$A30,#REF!,M$2) -> #REF! | O30: =SUM(B30:N30) -> #REF! | P30: TOTAL DE COLPORTAGEM
... A34: Despesas com Seminário | B34: =-SUMIFS(#REF!,#REF!,$A34,#REF!,B$2) -> #REF! | C34: =-SUMIFS(#REF!,#REF!,$A34,#REF!,C$2) -> #REF! | D34: =-SUMIFS(#REF!,#REF!,$A34,#REF!,D$2) -> #REF! | E34: =-SUMIFS(#REF!,#REF!,$A34,#REF!,E$2) -> #REF! | F34: =-SUMIFS(#REF!,#REF!,$A34,#REF!,F$2) -> #REF! | G34: =-SUMIFS(#REF!,#REF!,$A34,#REF!,G$2) -> #REF! | H34: =-SUMIFS(#REF!,#REF!,$A34,#REF!,H$2) -> #REF! | I34: =-SUMIFS(#REF!,#REF!,$A34,#REF!,I$2) -> #REF! | ... M34: =-SUMIFS(#REF!,#REF!,$A34,#REF!,M$2) -> #REF! | O34: =SUM(B34:N34) -> #REF! | P34: TOTAL DE COLPORTAGEM
A35: Total de Colportagem | B35: =SUM(B19:B34) -> #REF! | C35: =SUM(C19:C34) -> #REF! | D35: =SUM(D19:D34) -> #REF! | E35: =SUM(E19:E34) -> #REF! | F35: =SUM(F19:F34) -> #REF! | G35: =SUM(G19:G34) -> #REF! | H35: =SUM(H19:H34) -> #REF! | I35: =SUM(I19:I34) -> #REF! | ... M35: =SUM(M19:M34) -> #REF! | O35: =SUM(O19:O34) -> #REF! | P35: TOTAL DE COLPORTAGEM
A37: CEAPE (SAÍDAS)
A38: Agua, Luz, Telefone, IPTU - CEAPE | B38: =-SUMIFS(#REF!,#REF!,$A38,#REF!,B$2) -> #REF! | C38: =-SUMIFS(#REF!,#REF!,$A38,#REF!,C$2) -> #REF! | D38: =-SUMIFS(#REF!,#REF!,$A38,#REF!,D$2) -> #REF! | E38: =-SUMIFS(#REF!,#REF!,$A38,#REF!,E$2) -> #REF! | F38: =-SUMIFS(#REF!,#REF!,$A38,#REF!,F$2) -> #REF! | G38: =-SUMIFS(#REF!,#REF!,$A38,#REF!,G$2) -> #REF! | H38: =-SUMIFS(#REF!,#REF!,$A38,#REF!,H$2) -> #REF! | I38: =-SUMIFS(#REF!,#REF!,$A38,#REF!,I$2) -> #REF! | ... M38: =-SUMIFS(#REF!,#REF!,$A38,#REF!,M$2) -> #REF! | O38: =SUM(B38:N38) -> #REF! | P38: TOTAL DE GASTOS C/ CEAPE
A39: Ofertas p/ Coordenadores - CEAPE | B39: =-SUMIFS(#REF!,#REF!,$A39,#REF!,B$2) -> #REF! | C39: =-SUMIFS(#REF!,#REF!,$A39,#REF!,C$2) -> #REF! | D39: =-SUMIFS(#REF!,#REF!,$A39,#REF!,D$2) -> #REF! | E39: =-SUMIFS(#REF!,#REF!,$A39,#REF!,E$2) -> #REF! | F39: =-SUMIFS(#REF!,#REF!,$A39,#REF!,F$2) -> #REF! | G39: =-SUMIFS(#REF!,#REF!,$A39,#REF!,G$2) -> #REF! | H39: =-SUMIFS(#REF!,#REF!,$A39,#REF!,H$2) -> #REF! | I39: =-SUMIFS(#REF!,#REF!,$A39,#REF!,I$2) -> #REF! | ... M39: =-SUMIFS(#REF!,#REF!,$A39,#REF!,M$2) -> #REF! | O39: =SUM(B39:N39) -> #REF! | P39: TOTAL DE GASTOS C/ CEAPE
A40: Ofertas p/ Apoiadores - CEAPE | B40: =-SUMIFS(#REF!,#REF!,$A40,#REF!,B$2) -> #REF! | C40: =-SUMIFS(#REF!,#REF!,$A40,#REF!,C$2) -> #REF! | D40: =-SUMIFS(#REF!,#REF!,$A40,#REF!,D$2) -> #REF! | E40: =-SUMIFS(#REF!,#REF!,$A40,#REF!,E$2) -> #REF! | F40: =-SUMIFS(#REF!,#REF!,$A40,#REF!,F$2) -> #REF! | G40: =-SUMIFS(#REF!,#REF!,$A40,#REF!,G$2) -> #REF! | H40: =-SUMIFS(#REF!,#REF!,$A40,#REF!,H$2) -> #REF! | I40: =-SUMIFS(#REF!,#REF!,$A40,#REF!,I$2) -> #REF! | ... M40: =-SUMIFS(#REF!,#REF!,$A40,#REF!,M$2) -> #REF! | O40: =SUM(B40:N40) -> #REF! | P40: TOTAL DE GASTOS C/ CEAPE
A41: Participacoes em Conferencias/Reunioes Especiais | B41: =-SUMIFS(#REF!,#REF!,$A41,#REF!,B$2) -> #REF! | C41: =-SUMIFS(#REF!,#REF!,$A41,#REF!,C$2) -> #REF! | D41: =-SUMIFS(#REF!,#REF!,$A41,#REF!,D$2) -> #REF! | E41: =-SUMIFS(#REF!,#REF!,$A41,#REF!,E$2) -> #REF! | F41: =-SUMIFS(#REF!,#REF!,$A41,#REF!,F$2) -> #REF! | G41: =-SUMIFS(#REF!,#REF!,$A41,#REF!,G$2) -> #REF! | H41: =-SUMIFS(#REF!,#REF!,$A41,#REF!,H$2) -> #REF! | I41: =-SUMIFS(#REF!,#REF!,$A41,#REF!,I$2) -> #REF! | ... M41: =-SUMIFS(#REF!,#REF!,$A41,#REF!,M$2) -> #REF! | O41: =SUM(B41:N41) -> #REF! | P41: TOTAL DE GASTOS C/ CEAPE
A42: Oferta para necessidades pessoais de Ceapistas | B42: =-SUMIFS(#REF!,#REF!,$A42,#REF!,B$2) -> #REF! | C42: =-SUMIFS(#REF!,#REF!,$A42,#REF!,C$2) -> #REF! | D42: =-SUMIFS(#REF!,#REF!,$A42,#REF!,D$2) -> #REF! | E42: =-SUMIFS(#REF!,#REF!,$A42,#REF!,E$2) -> #REF! | F42: =-SUMIFS(#REF!,#REF!,$A42,#REF!,F$2) -> #REF! | G42: =-SUMIFS(#REF!,#REF!,$A42,#REF!,G$2) -> #REF! | H42: =-SUMIFS(#REF!,#REF!,$A42,#REF!,H$2) -> #REF! | I42: =-SUMIFS(#REF!,#REF!,$A42,#REF!,I$2) -> #REF! | ... M42: =-SUMIFS(#REF!,#REF!,$A42,#REF!,M$2) -> #REF! | O42: =SUM(B42:N42) -> #REF! | P42: TOTAL DE GASTOS C/ CEAPE
A43: Despesas com material de escritorio e grafico - CEAPE | B43: =-SUMIFS(#REF!,#REF!,$A43,#REF!,B$2) -> #REF! | C43: =-SUMIFS(#REF!,#REF!,$A43,#REF!,C$2) -> #REF! | D43: =-SUMIFS(#REF!,#REF!,$A43,#REF!,D$2) -> #REF! | E43: =-SUMIFS(#REF!,#REF!,$A43,#REF!,E$2) -> #REF! | F43: =-SUMIFS(#REF!,#REF!,$A43,#REF!,F$2) -> #REF! | G43: =-SUMIFS(#REF!,#REF!,$A43,#REF!,G$2) -> #REF! | H43: =-SUMIFS(#REF!,#REF!,$A43,#REF!,H$2) -> #REF! | I43: =-SUMIFS(#REF!,#REF!,$A43,#REF!,I$2) -> #REF! | ... M43: =-SUMIFS(#REF!,#REF!,$A43,#REF!,M$2) -> #REF! | O43: =SUM(B43:N43) -> #REF! | P43: TOTAL DE GASTOS C/ CEAPE
A44: Transporte - CEAPE | B44: =-SUMIFS(#REF!,#REF!,$A44,#REF!,B$2) -> #REF! | C44: =-SUMIFS(#REF!,#REF!,$A44,#REF!,C$2) -> #REF! | D44: =-SUMIFS(#REF!,#REF!,$A44,#REF!,D$2) -> #REF! | E44: =-SUMIFS(#REF!,#REF!,$A44,#REF!,E$2) -> #REF! | F44: =-SUMIFS(#REF!,#REF!,$A44,#REF!,F$2) -> #REF! | G44: =-SUMIFS(#REF!,#REF!,$A44,#REF!,G$2) -> #REF! | H44: =-SUMIFS(#REF!,#REF!,$A44,#REF!,H$2) -> #REF! | I44: =-SUMIFS(#REF!,#REF!,$A44,#REF!,I$2) -> #REF! | ... M44: =-SUMIFS(#REF!,#REF!,$A44,#REF!,M$2) -> #REF! | O44: =SUM(B44:N44) -> #REF! | P44: TOTAL DE GASTOS C/ CEAPE
A45: Transporte para apoiadores do CEAPE | B45: =-SUMIFS(#REF!,#REF!,$A45,#REF!,B$2) -> #REF! | C45: =-SUMIFS(#REF!,#REF!,$A45,#REF!,C$2) -> #REF! | D45: =-SUMIFS(#REF!,#REF!,$A45,#REF!,D$2) -> #REF! | E45: =-SUMIFS(#REF!,#REF!,$A45,#REF!,E$2) -> #REF! | F45: =-SUMIFS(#REF!,#REF!,$A45,#REF!,F$2) -> #REF! | G45: =-SUMIFS(#REF!,#REF!,$A45,#REF!,G$2) -> #REF! | H45: =-SUMIFS(#REF!,#REF!,$A45,#REF!,H$2) -> #REF! | I45: =-SUMIFS(#REF!,#REF!,$A45,#REF!,I$2) -> #REF! | ... M45: =-SUMIFS(#REF!,#REF!,$A45,#REF!,M$2) -> #REF! | O45: =SUM(B45:N45) -> #REF! | P45: TOTAL DE GASTOS C/ CEAPE
A46: Despesas médicas e odontológicas com Ceapistas | B46: =-SUMIFS(#REF!,#REF!,$A46,#REF!,B$2) -> #REF! | C46: =-SUMIFS(#REF!,#REF!,$A46,#REF!,C$2) -> #REF! | D46: =-SUMIFS(#REF!,#REF!,$A46,#REF!,D$2) -> #REF! | E46: =-SUMIFS(#REF!,#REF!,$A46,#REF!,E$2) -> #REF! | F46: =-SUMIFS(#REF!,#REF!,$A46,#REF!,F$2) -> #REF! | G46: =-SUMIFS(#REF!,#REF!,$A46,#REF!,G$2) -> #REF! | H46: =-SUMIFS(#REF!,#REF!,$A46,#REF!,H$2) -> #REF! | I46: =-SUMIFS(#REF!,#REF!,$A46,#REF!,I$2) -> #REF! | ... M46: =-SUMIFS(#REF!,#REF!,$A46,#REF!,M$2) -> #REF! | O46: =SUM(B46:N46) -> #REF! | P46: TOTAL DE GASTOS C/ CEAPE
...

Sheet FF_2017
A1: Fluxo Financeiro - Exercícios 2017
A3: RELATÓRIO FINANCEIRO | B3: Jan | C3: Fev | D3: Mar | E3: Abr | F3: Mai | G3: Jun | H3: Jul | I3: Ago | J3: Set | K3: Out | L3: Nov | M3: Dez | O3: Ano 2017 | Q3: Média Mensal | R3: %
B4: 1 | C4: 2 | D4: 3 | E4: 4 | F4: 5 | G4: 6 | H4: 7 | I4: 8 | J4: 9 | K4: 10 | L4: 11 | M4: 12 | Q4: =[1]MOV.FINANCEIRO!AC4 -> 12
A5: ENTRADAS
A6: Receitas de Ofertas | B6: 67332.3 | C6: 74679.8 | D6: 73026.17 | E6: 81345.5 | F6: 83040.57 | G6: 75250.29 | H6: 69567.04 | I6: 78988.38 | J6: 77651.95 | K6: 69979.2 | L6: 75261.81 | M6: 68080.23 | O6: =SUM(B6:N6) -> 894203.24 | Q6: =O6/$Q$4 -> 74516.937
A7: Outras Receitas | B7: 806.13 | C7: 1315.99 | D7: 1615.63 | E7: 2736.73 | F7: 2576.59 | G7: 3049.01 | H7: 8927.48 | I7: 13605.41 | J7: 2629.29 | K7: 2471.74 | L7: 2344.31 | M7: 2597.76 | O7: =SUM(B7:N7) -> 44676.07 | Q7: =O7/$Q$4 -> 3723.0058
A8: Total de Entradas | B8: =SUM(B6:B7) -> 68138.43 | C8: =SUM(C6:C7) -> 75995.79 | D8: =SUM(D6:D7) -> 74641.8 | E8: =SUM(E6:E7) -> 84082.23 | F8: =SUM(F6:F7) -> 85617.16 | G8: =SUM(G6:G7) -> 78299.3 | H8: =SUM(H6:H7) -> 78494.52 | I8: =SUM(I6:I7) -> 92593.79 | ... M8: =SUM(M6:M7) -> 70677.99 | O8: =SUM(O6:O7) -> 938879.31 | Q8: =SUM(Q6:Q7) -> 78239.942 | R8: 1
A10: SAIDAS - DESPESAS MINISTERIAIS
A11: Colportagem | B11: 29232.11 | C11: 35643.72 | D11: 27759.8 | E11: 36253.23 | F11: 29746.11 | G11: 32096.9 | H11: 43332.97 | I11: 47710.5 | J11: 41125 | K11: 49418.09 | L11: 46753.73 | M11: 41147.15 | O11: =SUM(B11:N11) -> 460219.31 | Q11: =O11/$Q$4 -> 38351.609 | R11: =O11/$O$8 -> 0.49017941
A12: CEAPE | B12: 259.7 | C12: 0 | D12: 300 | E12: 0 | F12: 0 | G12: 0 | H12: 0 | I12: 0 | J12: 0 | K12: 0 | L12: 0 | M12: 0 | O12: =SUM(B12:N12) -> 559.7 | Q12: =O12/$Q$4 -> 46.641667 | R12: =O12/$O$8 -> 0.00059613626
A13: Bookafé | B13: 0 | C13: 0 | D13: 0 | E13: 0 | F13: 0 | G13: 0 | H13: 0 | I13: 0 | J13: 0 | K13: 0 | L13: 0 | M13: 0 | O13: =SUM(B13:N13) -> 0 | Q13: =O13/$Q$4 -> 0 | R13: =O13/$O$8 -> 0
A14: Angola/África | B14: 3111.4 | C14: 13612.45 | D14: 5411.25 | E14: 24009.04 | F14: 18975.31 | G14: 25761.62 | H14: 4686.14 | I14: 2423.29 | J14: 7434 | K14: 15701.06 | L14: 0 | M14: 0 | O14: =SUM(B14:N14) -> 121125.56 | Q14: =O14/$Q$4 -> 10093.797 | R14: =O14/$O$8 -> 0.12901079
A15: Estados Unidos | B15: 0 | C15: 0 | D15: 0 | E15: 0 | F15: 0 | G15: 0 | H15: 0 | I15: 0 | J15: 0 | K15: 0 | L15: 0 | M15: 0 | O15: =SUM(B15:N15) -> 0 | Q15: =O15/$Q$4 -> 0 | R15: =O15/$O$8 -> 0
A16: Obreiros e Apoiadores | B16: 8139.52 | C16: 7099.35 | D16: 6257.71 | E16: 9768.22 | F16: 11527.52 | G16: 9695.07 | H16: 9554.84 | I16: 25820.12 | J16: 10492.18 | K16: 4588.24 | L16: 10788.24 | M16: 6611.11 | O16: =SUM(B16:N16) -> 120342.12 | Q16: =O16/$Q$4 -> 10028.51 | R16: =O16/$O$8 -> 0.12817635
A17: Gastos Específicos | B17: 3600 | C17: 3500 | D17: 3500 | E17: 3500 | F17: 3500 | G17: 3500 | H17: 3500 | I17: 3500 | J17: 3500 | K17: 3500 | L17: 3500 | M17: 2000 | O17: =SUM(B17:N17) -> 40600 | Q17: =O17/$Q$4 -> 3383.3333 | R17: =O17/$O$8 -> 0.043243045
A18: Total de Despesas Ministeriais | B18: =SUM(B11:B17) -> 44342.73 | C18: =SUM(C11:C17) -> 59855.52 | D18: =SUM(D11:D17) -> 43228.76 | E18: =SUM(E11:E17) -> 73530.49 | F18: =SUM(F11:F17) -> 63748.94 | G18: =SUM(G11:G17) -> 71053.59 | H18: =SUM(H11:H17) -> 61073.95 | I18: =SUM(I11:I17) -> 79453.91 | ... M18: =SUM(M11:M17) -> 49758.26 | O18: =SUM(O11:O17) -> 742846.69 | Q18: =SUM(Q11:Q17) -> 61903.891 | R18: =SUM(R11:R17) -> 0.79120573
A19: SAIDAS - DESPESAS ADMINISTRATIVAS
A20: Investimentos | B20: 0 | C20: 0 | D20: 0 | E20: 0 | F20: 0 | G20: 0 | H20: 0 | I20: 0 | J20: 0 | K20: 0 | L20: 0 | M20: 0 | O20: =SUM(B20:N20) -> 0 | Q20: =O20/$Q$4 -> 0 | R20: =O20/$O$8 -> 0
A21: Despesas Gerais | B21: 6087.99 | C21: 5435.7 | D21: 2551 | E21: 4004.65 | F21: 2383.23 | G21: 2378.23 | H21: 4271.31 | I21: 3648.26 | J21: 4354.96 | K21: 4087.02 | L21: 2813.04 | M21: 1682.54 | O21: =SUM(B21:N21) -> 43697.93 | Q21: =O21/$Q$4 -> 3641.4942 | R21: =O21/$O$8 -> 0.046542649
A22: Obrigacoes Trabalhistas e Sociais | B22: 11450.25 | C22: 6722.848 | D22: 6969.32 | E22: 6925.87 | F22: 7289.69 | G22: 7984.74 | H22: 7103.8 | I22: 9004.75 | J22: 6908.75 | K22: 6293.73 | L22: 9530.8 | M22: 10802.76 | O22: =SUM(B22:N22) -> 96987.308 | Q22: =O22/$Q$4 -> 8082.2757 | R22: =O22/$O$8 -> 0.10330115
A23: Despesas Financeiras e Tributárias | B23: 2407.1 | C23: 1846.76 | D23: 2347.91 | E23: 2229.43 | F23: 2638.24 | G23: 2403.43 | H23: 2128.26 | I23: 2416.56 | J23: 2150.94 | K23: 2540.95 | L23: 2349.02 | M23: 2251.19 | O23: =SUM(B23:N23) -> 27709.79 | Q23: =O23/$Q$4 -> 2309.1492 | R23: =O23/$O$8 -> 0.029513687
A24: Total de Despesas Administrativas | B24: =SUM(B20:B23) -> 19945.34 | C24: =SUM(C20:C23) -> 14005.308 | D24: =SUM(D20:D23) -> 11868.23 | E24: =SUM(E20:E23) -> 13159.95 | F24: =SUM(F20:F23) -> 12311.16 | G24: =SUM(G20:G23) -> 12766.4 | H24: =SUM(H20:H23) -> 13503.37 | I24: =SUM(I20:I23) -> 15069.57 | ... M24: =SUM(M20:M23) -> 14736.49 | O24: =SUM(O20:O23) -> 168395.03 | Q24: =O24/$Q$4 -> 14032.919 | R24: =SUM(R20:R23) -> 0.17935748
A26: Total de Saidas | B26: =B18+B24 -> 64288.07 | C26: =C18+C24 -> 73860.828 | D26: =D18+D24 -> 55096.99 | E26: =E18+E24 -> 86690.44 | F26: =F18+F24 -> 76060.1 | G26: =G18+G24 -> 83819.99 | H26: =H18+H24 -> 74577.32 | I26: =I18+I24 -> 94523.48 | ... M26: =M18+M24 -> 64494.75 | O26: =O18+O24 -> 911241.72 | Q26: =O26/$Q$4 -> 75936.81 | R26: =SUM(R22:R25) -> 0.31217231
A27: REPASSES E INTERMEDIAÇÕES
A28: Bookafé Corporate | B28: 0 | C28: 0 | D28: 0 | E28: 0 | F28: 0 | G28: 0 | H28: 0 | I28: 0 | J28: 0 | K28: 0 | L28: 0 | M28: 0 | O28: =SUM(B28:N28) -> 0
A29: América do Norte | B29: 0 | C29: 0 | D29: 0 | E29: 0 | F29: 0 | G29: 0 | H29: 0 | I29: 0 | J29: 0 | K29: 0 | L29: 0 | M29: 0 | O29: =SUM(B29:N29) -> 0
A30: Van - CEAPE Foz Iguaçu | B30: 0 | C30: 0 | D30: 0 | E30: 0 | F30: 0 | G30: 0 | H30: 0 | I30: 0 | J30: 0 | K30: 0 | L30: 0 | M30: 0 | O30: =SUM(B30:N30) -> 0
A31: Total de Repasses e Intermediações | B31: =SUM(B28:B30) -> 0 | C31: =SUM(C28:C30) -> 0 | D31: =SUM(D28:D30) -> 0 | E31: =SUM(E28:E30) -> 0 | F31: =SUM(F28:F30) -> 0 | G31: =SUM(G28:G30) -> 0 | H31: =SUM(H28:H30) -> 0 | I31: =SUM(I28:I30) -> 0 | ... M31: =SUM(M28:M30) -> 0 | O31: =SUM(O28:O30) -> 0 | Q31: =O31/$Q$4 -> 0 | R31: =-O31/O8 -> 0
A32: GASTOS SUSTENTÁVEIS
A33: Servico de Conferencias | B33: 0 | C33: 0 | D33: 5825 | E33: -18058.67 | F33: 18522 | G33: 0 | H33: -41.9 | I33: 2009 | J33: 0 | K33: 23961.29 | L33: -30187.413 | M33: 6410 | O33: =SUM(B33:N33) -> 8439.307
A34: Total de Gastos Sustentáveis | B34: =B33 -> 0 | C34: =C33 -> 0 | D34: =D33 -> 5825 | E34: =E33 -> -18058.67 | F34: =F33 -> 18522 | G34: =G33 -> 0 | H34: =H33 -> -41.9 | I34: =I33 -> 2009 | ... M34: =M33 -> 6410 | O34: =O33 -> 8439.307
A36: Movimentação Financeira | B36: =B8-B18-B24+B31+B33 -> 3850.36 | C36: =C8-C18-C24+C31+C33 -> 2134.962 | D36: =D8-D18-D24+D31+D33 -> 25369.81 | E36: =E8-E18-E24+E31+E33 -> -20666.88 | F36: =F8-F18-F24+F31+F33 -> 28079.06 | G36: =G8-G18-G24+G31+G33 -> -5520.69 | H36: =H8-H18-H24+H31+H33 -> 3875.3 | I36: =I8-I18-I24+I31+I33 -> 79.31 | ... M36: =M8-M18-M24+M31+M33 -> 12593.24 | O36: =O8-O18-O24+O31+O34 -> 36076.899 | Q36: =O36/$Q$4 -> 3006.4082 | R36: =O36/O8 -> 0.038425492
A38: Saldo das Disponibilidades | B38: =[1]MOV.FINANCEIRO!M4+B36 -> 121435.75 | C38: =B38+C36 -> 123570.71 | D38: =C38+D36 -> 148940.52 | E38: =D38+E36 -> 128273.64 | F38: =E38+F36 -> 156352.7 | G38: =F38+G36 -> 150832.01 | H38: =G38+H36 -> 154707.31 | I38: =H38+I36 -> 154786.62 | J38: =I38+J36 -> 159102.03 | ... M38: =L38+M36 -> 153662.29 | O38: =M38 -> 153662.29
A41: SALDO DAS DISPONIBILIDADES | B41: Jan | C41: Fev | D41: Mar | E41: Abr | F41: Mai | G41: Jun | H41: Jul | I41: Ago | J41: Set | K41: Out | L41: Nov | M41: Dez
A42: Caixa | B42: 1238.13 | C42: 4144.87 | D42: 3703.06 | E42: 2208.43 | F42: 317.25 | G42: 1122.78 | H42: 3134.75 | I42: 10083.02 | J42: 2305.95 | K42: 10775.23 | L42: 11359.31 | M42: 3087.09
A43: Bancos | B43: 862 | C43: 694.06 | D43: 9552.22 | E43: 3186.63 | F43: 10887.4 | G43: 25691.39 | H43: 5844.65 | I43: 4169.3 | J43: 12326.37 | K43: 38346.76 | L43: 10534.06 | M43: 10629.72
A44: Aplicação Financeira | B44: 119335.62 | C44: 118731.78 | D44: 135685.24 | E44: 122878.58 | F44: 145148.05 | G44: 124017.84 | H44: 145727.91 | I44: 140534.3 | J44: 144469.71 | K44: 120263.18 | L44: 119175.68 | M44: 139945.48
A45: Empréstimos Contraídos | B45: 0 | C45: 0 | D45: 0 | E45: 0 | F45: 0 | G45: 0 | H45: 0 | I45: 0 | J45: 0 | K45: 0 | L45: 0 | M45: 0
B46: =SUM(B42:B44)-B45 -> 121435.75 | C46: =SUM(C42:C44)-C45 -> 123570.71 | D46: =SUM(D42:D44)-D45 -> 148940.52 | E46: =SUM(E42:E44)-E45 -> 128273.64 | F46: =SUM(F42:F44)-F45 -> 156352.7 | G46: =SUM(G42:G44)-G45 -> 150832.01 | H46: =SUM(H42:H44)-H45 -> 154707.31 | I46: =SUM(I42:I44)-I45 -> 154786.62 | ... M46: =SUM(M42:M44)-M45 -> 153662.29
B47: =B46-B38 -> 0 | C47: =C46-C38 -> -0.002 | D47: =D46-D38 -> -0.0019999999 | E47: =E46-E38 -> -0.0019999999 | F47: =F46-F38 -> -0.0019999999 | G47: =G46-G38 -> -0.0019999999 | H47: =H46-H38 -> -0.0019999999 | I47: =I46-I38 -> -0.0019999999 | ... M47: =M46-M38 -> 0.001

Sheet FF_2016
A1: Fluxo Financeiro - Exercícios 2016
A3: RELATÓRIO FINANCEIRO - 2016 | B3: Jan | C3: Fev | D3: Mar | E3: Abr | F3: Mai | G3: Jun | H3: Jul | I3: Ago | J3: Set | K3: Out | L3: Nov | M3: Dez | Q3: Média Mensal | R3: %
B4: 1 | C4: 2 | D4: 3 | E4: 4 | F4: 5 | G4: 6 | H4: 7 | I4: 8 | J4: 9 | K4: 10 | L4: 11 | M4: 12 | Q4: =[2]MOV.FINANCEIRO!AC4 -> 12
A5: ENTRADAS
A6: Receitas de Ofertas | B6: 84481.97 | C6: 66913.09 | D6: 72421.4 | E6: 62988.29 | F6: 61003.64 | G6: 66632.03 | H6: 78166.69 | I6: 78189.61 | J6: 91239.21 | K6: 75333.33 | L6: 113148.69 | M6: 71380.58 | O6: =SUM(B6:N6) -> 921898.53 | Q6: =O6/$Q$4 -> 76824.877
A7: Outras Receitas | B7: 2857.3 | C7: 3552.66 | D7: 3400.97 | E7: 3378.58 | F7: 2455.58 | G7: 2247.3 | H7: 3486.24 | I7: 5143.49 | J7: 5077.2 | K7: 1259.06 | L7: 615.94 | M7: 875.13 | O7: =SUM(B7:N7) -> 34349.45 | Q7: =O7/$Q$4 -> 2862.4542
A8: Total de Entradas | B8: 87339.27 | C8: 70465.75 | D8: 75822.37 | E8: 66366.87 | F8: 63459.22 | G8: 68879.33 | H8: 81652.93 | I8: 83333.1 | J8: 96316.41 | K8: 76592.39 | L8: 113764.63 | M8: 72255.71 | O8: =SUM(O6:O7) -> 956247.98 | Q8: =SUM(Q6:Q7) -> 79687.332 | R8: 1
A10: SAIDAS - DESPESAS MINISTERIAIS
A11: Colportagem | B11: 37644.72 | C11: 19680.78 | D11: 41342.46 | E11: 35484.84 | F11: 32408.96 | G11: 77362.04 | H11: 40931.06 | I11: 42845.79 | J11: 34605.24 | K11: 40507.51 | L11: 31585.31 | M11: 39881.39 | O11: =SUM(B11:N11) -> 474280.1 | Q11: =O11/$Q$4 -> 39523.342 | R11: =O11/$O$8 -> 0.49598024
A12: CEAPE | B12: 13317.8 | C12: 13924.71 | D12: 4413.91 | E12: 10225.35 | F12: 8816.54 | G12: 14505.37 | H12: 18271.13 | I12: 10816.08 | J12: 14782.49 | K12: 10821.92 | L12: 11772.15 | M12: 6390.74 | O12: =SUM(B12:N12) -> 138058.19 | Q12: =O12/$Q$4 -> 11504.849 | R12: =O12/$O$8 -> 0.14437488
A13: Bookafé | B13: 0 | C13: 0 | D13: 0 | E13: 0 | F13: 0 | G13: 0 | H13: 0 | I13: 0 | J13: 0 | K13: 0 | L13: 0 | M13: 0 | O13: =SUM(B13:N13) -> 0 | Q13: =O13/$Q$4 -> 0 | R13: =O13/$O$8 -> 0
A14: Angola/África | B14: 1696 | C14: 19409.78 | D14: 4260.45 | E14: 0 | F14: 0 | G14: 0 | H14: 13220.27 | I14: 11451.72 | J14: 12705.73 | K14: 14599.65 | L14: 26415.5 | M14: 35334.22 | O14: =SUM(B14:N14) -> 139093.32 | Q14: =O14/$Q$4 -> 11591.11 | R14: =O14/$O$8 -> 0.14545737
A15: Estados Unidos | B15: 3035.07 | C15: 2055 | D15: 1980 | E15: 1880 | F15: 1830 | G15: 1895 | H15: 2810 | I15: 570 | J15: 4880 | K15: 1700 | L15: 1685 | M15: 1700 | O15: =SUM(B15:N15) -> 26020.07 | Q15: =O15/$Q$4 -> 2168.3392 | R15: =O15/$O$8 -> 0.027210588
A16: Obreiros e Apoiadores | B16: 10300.5 | C16: 7943.01 | D16: 8162.84 | E16: 10559.1 | F16: 10088.62 | G16: 12541.96 | H16: 8374.69 | I16: 13504.24 | J16: 8174.98 | K16: 10242.12 | L16: 7139.52 | M16: 14830.09 | O16: =SUM(B16:N16) -> 121861.67 | Q16: =O16/$Q$4 -> 10155.139 | R16: =O16/$O$8 -> 0.12743731
A17: Gastos Específicos | B17: 3650 | C17: 4628.82 | D17: 6617.56 | E17: 4150 | F17: 4735.99 | G17: 5071.63 | H17: 9174.28 | I17: 5184.06 | J17: 4600 | K17: 5242 | L17: 6134.14 | M17: 4158.16 | O17: =SUM(B17:N17) -> 63346.64 | Q17: =O17/$Q$4 -> 5278.8867 | R17: =O17/$O$8 -> 0.066244992
A18: Total de Despesas Ministeriais | B18: 69644.09 | C18: 67642.1 | D18: 66777.22 | E18: 62299.29 | F18: 57880.11 | G18: 111376 | H18: 92781.43 | I18: 84371.89 | J18: 79748.44 | K18: 83113.2 | L18: 84731.62 | M18: 102294.6 | O18: =SUM(O11:O17) -> 962659.99 | Q18: =SUM(Q11:Q17) -> 80221.666 | R18: =SUM(R11:R17) -> 1.0067054
A19: SAIDAS - DESPESAS ADMINISTRATIVAS
A20: Investimentos | B20: 0 | C20: 0 | D20: 0 | E20: 0 | F20: 0 | G20: 0 | H20: 1993.97 | I20: 0 | J20: 0 | K20: 0 | L20: 0 | M20: 0 | O20: =SUM(B20:N20) -> 1993.97 | Q20: =O20/$Q$4 -> 166.16417 | R20: =O20/$O$8 -> 0.0020852018
A21: Despesas Gerais | B21: 2472.93 | C21: 8881.85 | D21: 5459.18 | E21: 3921.1 | F21: 4307.46 | G21: 6501.14 | H21: 13074.4 | I21: 8652.83 | J21: 6839.51 | K21: 5202.58 | L21: 3570.93 | M21: 2081.48 | O21: =SUM(B21:N21) -> 70965.39 | Q21: =O21/$Q$4 -> 5913.7825 | R21: =O21/$O$8 -> 0.074212329
A22: Obrigacoes Trabalhistas e Sociais | B22: 8616.13 | C22: 5595 | D22: 8636.01 | E22: 7972.25 | F22: 7474.07 | G22: 8149.99 | H22: 7544.27 | I22: 8125.18 | J22: 9371.07 | K22: 7428.75 | L22: 14304.15 | M22: 11652.07 | O22: =SUM(B22:N22) -> 104868.94 | Q22: =O22/$Q$4 -> 8739.0783 | R22: =O22/$O$8 -> 0.1096671
A23: Despesas Financeiras e Tributárias | B23: 1439.82 | C23: 993.5 | D23: 1563.86 | E23: 2207.63 | F23: 2255.04 | G23: 2246.18 | H23: 2273.46 | I23: 2310.03 | J23: 2039.66 | K23: 2183.99 | L23: 2186.8 | M23: 2259.38 | O23: =SUM(B23:N23) -> 23959.35 | Q23: =O23/$Q$4 -> 1996.6125 | R23: =O23/$O$8 -> 0.025055582
A24: Total de Despesas Administrativas | B24: 12528.88 | C24: 15470.35 | D24: 15659.05 | E24: 14100.98 | F24: 14036.57 | G24: 16897.31 | H24: 24886.1 | I24: 19088.04 | J24: 18250.24 | K24: 14815.32 | L24: 20061.88 | M24: 15992.93 | O24: =SUM(O20:O23) -> 201787.65 | Q24: =O24/$Q$4 -> 16815.638 | R24: =SUM(R20:R23) -> 0.21102021
A26: Total de Saidas | B26: =B18+B24 -> 82172.97 | C26: =C18+C24 -> 83112.45 | D26: =D18+D24 -> 82436.27 | E26: =E18+E24 -> 76400.27 | F26: =F18+F24 -> 71916.68 | G26: =G18+G24 -> 128273.31 | H26: =H18+H24 -> 117667.53 | I26: =I18+I24 -> 103459.93 | ... M26: =M18+M24 -> 118287.53 | O26: =O18+O24 -> 1164447.6 | Q26: =O26/$Q$4 -> 97037.303 | R26: =SUM(R22:R25) -> 0.34574289
A27: REPASSES E INTERMEDIAÇÕES
A28: Bookafé Corporate | B28: 0 | C28: 0 | D28: 0 | E28: 0 | F28: 0 | G28: 0 | H28: 0 | I28: 0 | J28: 0 | K28: 0 | L28: 0 | M28: 0 | O28: =SUM(B28:N28) -> 0
A29: América do Norte | B29: 0 | C29: 0 | D29: 0 | E29: 0 | F29: 0 | G29: 0 | H29: 0 | I29: 0 | J29: 0 | K29: 0 | L29: 0 | M29: 0 | O29: =SUM(B29:N29) -> 0
A30: Van - CEAPE Foz Iguaçu | B30: 0 | C30: 0 | D30: 0 | E30: 0 | F30: 0 | G30: 0 | H30: 0 | I30: 0 | J30: 0 | K30: 0 | L30: 0 | M30: 0 | O30: =SUM(B30:N30) -> 0
A31: Total de Repasses e Intermediações | B31: 0 | C31: 0 | D31: 0 | E31: 0 | F31: 0 | G31: 0 | H31: 0 | I31: 0 | J31: 0 | K31: 0 | L31: 0 | M31: 0 | O31: =SUM(O28:O30) -> 0 | Q31: =O31/$Q$4 -> 0 | R31: =-O31/O8 -> 0
A33: GASTOS SUSTENTÁVEIS
A34: Conferencia Regional | B34: 0 | C34: -19.98 | D34: -14090.89 | E34: 0 | F34: 0 | G34: 0 | H34: 0 | I34: 0 | J34: 0 | K34: -17617.24 | L34: 41330.54 | M34: 0 | O34: =SUM(B34:N34) -> 9602.43 | Q34: =O34/$Q$4 -> 800.2025 | R34: =O34/$O$8 -> 0.010041778
A35: Total de Gastos Sustentáveis | B35: 0 | C35: -19.98 | D35: -14090.89 | E35: 0 | F35: 0 | G35: 0 | H35: 0 | I35: 0 | J35: 0 | K35: -17617.24 | L35: 41330.54 | M35: 0 | O35: =O34 -> 9602.43 | Q35: =O35/$Q$4 -> 800.2025 | R35: =SUM(R31:R34) -> 0.010041778
A37: Movimentação Financeira | B37: 5166.3 | C37: -12666.68 | D37: -20704.79 | E37: -10033.4 | F37: -8457.46 | G37: -59393.98 | H37: -36014.6 | I37: -20126.83 | J37: -1682.27 | K37: -38953.37 | L37: 50301.67 | M37: -46031.82 | O37: =O8-O18-O24+O31+O35 -> -198597.23 | Q37: =O37/$Q$4 -> -16549.769 | R37: =O37/O8 -> -0.20768382
A39: Saldo das Disponibilidades | B39: 321348.92 | C39: 308682.24 | D39: 287977.45 | E39: 277944.05 | F39: 269486.59 | G39: 210092.61 | H39: 174078.01 | I39: 153951.18 | J39: 152268.91 | K39: 113315.54 | L39: 163617.21 | M39: 117585.39 | O39: =M39 -> 117585.39
A42: SALDO DAS DISPONIBILIDADES | B42: Jan | C42: Fev | D42: Mar | E42: Abr | F42: Mai | G42: Jun | H42: Jul | I42: Ago | J42: Set | K42: Out | L42: Nov | M42: Dez
A43: Caixa | B43: 613.62 | C43: 3210.98 | D43: 1229.36 | E43: 3137.93 | F43: 395.33 | G43: 141.2 | H43: 2458.52 | I43: 3432.65 | J43: 3957.58 | K43: 4090.52 | L43: 39166.41 | M43: 144.33
A44: Bancos | B44: 9603.11 | C44: 9425.53 | D44: 2 | E44: 424.3 | F44: 366.7 | G44: 309.1 | H44: 244.3 | I44: 179.5 | J44: 114.7 | K44: 12889.9 | L44: 3193.66 | M44: 2613.17
A45: Aplicação Financeira | B45: 311132.19 | C45: 303045.73 | D45: 292056.09 | E45: 281381.82 | F45: 273989.56 | G45: 209642.31 | H45: 171375.19 | I45: 150339.03 | J45: 156196.63 | K45: 96335.12 | L45: 121257.14 | M45: 114827.89
A46: Empréstimos Contraídos | B46: 0 | C46: 7000 | D46: 5310 | E46: 7000 | F46: 5265 | G46: 0 | H46: 0 | I46: 0 | J46: 8000 | K46: 0 | L46: 0 | M46: 0
B47: 321348.92 | C47: 308682.24 | D47: 287977.45 | E47: 277944.05 | F47: 269486.59 | G47: 210092.61 | H47: 174078.01 | I47: 153951.18 | J47: 152268.91 | K47: 113315.54 | L47: 163617.21 | M47: 117585.39
A49: Movimentação Financeira | B49: 5166.3 | C49: -12666.68 | D49: -20704.79 | E49: -10033.4 | F49: -8457.46 | G49: -59393.98 | H49: -36014.6 | I49: -20126.83 | J49: -1682.27 | K49: -38953.37 | L49: 50301.67 | M49: -46031.82
...

Sheet Graficos_2018
A1: Relatórios Financeiros - Comparativo 2016, 2017 e 2018
A2: =A5 -> Obreiros e Apoiadores
A5: Obreiros e Apoiadores | B5: Jan | C5: Fev | D5: Mar | E5: Abr | F5: Mai | G5: Jun | H5: Jul | I5: Ago | J5: Set | K5: Out | L5: Nov | M5: Dez | O5: Jan a Dez | Q5: Média Mensal
B6: 2 | C6: 3 | D6: 4 | E6: 5 | F6: 6 | G6: 7 | H6: 8 | I6: 9 | J6: 10 | K6: 11 | L6: 12 | M6: 13
A7: Exercício 2016 | B7: =VLOOKUP($A$5,FF_2016!$A:$M,B6,0) -> 10300.5 | C7: =VLOOKUP($A$5,FF_2016!$A:$M,C6,0) -> 7943.01 | D7: =VLOOKUP($A$5,FF_2016!$A:$M,D6,0) -> 8162.84 | E7: =VLOOKUP($A$5,FF_2016!$A:$M,E6,0) -> 10559.1 | F7: =VLOOKUP($A$5,FF_2016!$A:$M,F6,0) -> 10088.62 | G7: =VLOOKUP($A$5,FF_2016!$A:$M,G6,0) -> 12541.96 | H7: =VLOOKUP($A$5,FF_2016!$A:$M,H6,0) -> 8374.69 | I7: =VLOOKUP($A$5,FF_2016!$A:$M,I6,0) -> 13504.24 | ... M7: =VLOOKUP($A$5,FF_2016!$A:$M,M6,0) -> 14830.09 | N7: 2016 | O7: =SUM(B7:M7) -> 121861.67 | P7: Entradas | Q7: =O7/12 -> 10155.139
A8: Exercício 2017 | B8: =VLOOKUP($A$5,FF_2017!$A$3:$O$38,B$6,0) -> 8139.52 | C8: =VLOOKUP($A$5,FF_2017!$A$3:$O$38,C$6,0) -> 7099.35 | D8: =VLOOKUP($A$5,FF_2017!$A$3:$O$38,D$6,0) -> 6257.71 | E8: =VLOOKUP($A$5,FF_2017!$A$3:$O$38,E$6,0) -> 9768.22 | F8: =VLOOKUP($A$5,FF_2017!$A$3:$O$38,F$6,0) -> 11527.52 | G8: =VLOOKUP($A$5,FF_2017!$A$3:$O$38,G$6,0) -> 9695.07 | H8: =VLOOKUP($A$5,FF_2017!$A$3:$O$38,H$6,0) -> 9554.84 | I8: =VLOOKUP($A$5,FF_2017!$A$3:$O$38,I$6,0) -> 25820.12 | ... M8: =VLOOKUP($A$5,FF_2017!$A$3:$O$38,M$6,0) -> 6611.11 | N8: 2017 | O8: =SUM(B8:M8) -> 120342.12
A9: Exercício 2018 | B9: =VLOOKUP($A$5,#REF!,B$6,0) -> #REF! | C9: =VLOOKUP($A$5,#REF!,C$6,0) -> #REF! | D9: =VLOOKUP($A$5,#REF!,D$6,0) -> #REF! | E9: =VLOOKUP($A$5,#REF!,E$6,0) -> #REF! | F9: =VLOOKUP($A$5,#REF!,F$6,0) -> #REF! | G9: =VLOOKUP($A$5,#REF!,G$6,0) -> #REF! | H9: =VLOOKUP($A$5,#REF!,H$6,0) -> #REF! | I9: =VLOOKUP($A$5,#REF!,I$6,0) -> #REF! | ... M9: =VLOOKUP($A$5,#REF!,M$6,0) -> #REF! | N9: 2018 | O9: =SUM(B9:M9) -> #REF! | P9: Entradas | Q9: =O9/12 -> #REF!
B11: 2 | C11: 3 | D11: 4 | E11: 5 | F11: 6 | G11: 7 | H11: 8 | I11: 9 | J11: 10 | K11: 11 | L11: 12 | M11: 13 | O11: 15 | Q11: =[3]MOV.FINANCEIRO!AJ4 -> 12

Sheet Comparativo.Entradas
A1: Comparativo das Entradas - Exercícios 2016, 2017 e 2018
F3: Variação
A4: RELATÓRIO FINANCEIRO | B4: Ano 2016 | C4: Ano 2017 | D4: Ano 2018 | F4: 2016/17 | G4: 2017/18
D5: =#REF! -> #REF!
A6: RECEITAS DE OFERTAS
A7: Ofertas Regulares | B7: 726570.71 | C7: 641525.16 | D7: =VLOOKUP(A7,#REF!,15,0) -> #REF! | F7: =C7-B7 -> -85045.55 | G7: =D7-C7 -> #REF!
A8: Ofertas p/ Africa/Angola e Fundo da Obra | B8: 179367.67 | C8: 194886.85 | D8: =VLOOKUP(A8,#REF!,15,0) -> #REF! | F8: =C8-B8 -> 15519.18 | G8: =D8-C8 -> #REF!
A9: Ofertas p/ Aquisicao de Vans | B9: 0 | C9: 0 | D9: =VLOOKUP(A9,#REF!,15,0) -> #REF! | F9: =C9-B9 -> 0 | G9: =D9-C9 -> #REF!
A10: Ofertas Especiais do MRM | B10: 0 | C10: 0 | D10: =VLOOKUP(A10,#REF!,15,0) -> #REF! | F10: =C10-B10 -> 0 | G10: =D10-C10 -> #REF!
A11: Ofertas de Conferencias Microrregionais | B11: 0 | C11: 55182.73 | D11: =VLOOKUP(A11,#REF!,15,0) -> #REF! | F11: =C11-B11 -> 55182.73 | G11: =D11-C11 -> #REF!
A12: Ofertas p/ Apostolo | B12: 0 | C12: 0 | D12: =VLOOKUP(A12,#REF!,15,0) -> #REF! | F12: =C12-B12 -> 0 | G12: =D12-C12 -> #REF!
A13: Ofertas p/ CEAPE | B13: 13718.15 | C13: 2010 | D13: =VLOOKUP(A13,#REF!,15,0) -> #REF! | F13: =C13-B13 -> -11708.15 | G13: =D13-C13 -> #REF!
A14: Tratamento Médico do Reinaldo | B14: 0 | C14: 0 | D14: =VLOOKUP(A14,#REF!,15,0) -> #REF! | F14: =C14-B14 -> 0 | G14: =D14-C14 -> #REF!
A15: Ofertas Diversas | B15: 2242 | C15: 598.5 | D15: =VLOOKUP(A15,#REF!,15,0) -> #REF! | F15: =C15-B15 -> -1643.5 | G15: =D15-C15 -> #REF!
A16: Total das Receitas de Ofertas | B16: =SUM(B7:B15) -> 921898.53 | C16: =SUM(C7:C15) -> 894203.24 | D16: =SUM(D7:D15) -> #REF! | F16: =SUM(F7:F15) -> -27695.29 | G16: =SUM(G7:G15) -> #REF!
F17: =IFERROR(C16/B16-1,"") -> -0.030041582 | G17: =IFERROR(D16/C16-1,"")
A18: OUTRAS RECEITAS
A19: Alienacao de Bens Ativo Permanente | B19: 0 | C19: 17474 | D19: =VLOOKUP(A19,#REF!,15,0) -> #REF! | F19: =C19-B19 -> 17474 | G19: =D19-C19 -> #REF!
